[2024-02-10 00:02:52 +0000] [147379] [INFO] Starting gunicorn 21.2.0
[2024-02-10 00:02:52 +0000] [147379] [INFO] Listening at: http://0.0.0.0:8000 (147379)
[2024-02-10 00:02:52 +0000] [147379] [INFO] Using worker: sync
[2024-02-10 00:02:52 +0000] [147380] [INFO] Booting worker with pid: 147380
[2024-02-10 00:03:39 +0000] [147953] [INFO] Starting gunicorn 21.2.0
[2024-02-10 00:03:39 +0000] [147953] [ERROR] Connection in use: ('0.0.0.0', 8000)
[2024-02-10 00:03:39 +0000] [147953] [ERROR] Retrying in 1 second.
[2024-02-10 00:03:40 +0000] [147953] [ERROR] Connection in use: ('0.0.0.0', 8000)
[2024-02-10 00:03:40 +0000] [147953] [ERROR] Retrying in 1 second.
[2024-02-10 00:03:41 +0000] [147953] [ERROR] Connection in use: ('0.0.0.0', 8000)
[2024-02-10 00:03:41 +0000] [147953] [ERROR] Retrying in 1 second.
[2024-02-10 00:03:42 +0000] [147953] [ERROR] Connection in use: ('0.0.0.0', 8000)
[2024-02-10 00:03:42 +0000] [147953] [ERROR] Retrying in 1 second.
[2024-02-10 00:03:43 +0000] [147953] [ERROR] Connection in use: ('0.0.0.0', 8000)
[2024-02-10 00:03:43 +0000] [147953] [ERROR] Retrying in 1 second.
[2024-02-10 00:03:44 +0000] [147953] [ERROR] Can't connect to ('0.0.0.0', 8000)
[2024-02-10 00:04:01 +0000] [148445] [INFO] Starting gunicorn 21.2.0
[2024-02-10 00:04:01 +0000] [148445] [INFO] Listening at: http://0.0.0.0:8000 (148445)
[2024-02-10 00:04:01 +0000] [148445] [INFO] Using worker: sync
[2024-02-10 00:04:01 +0000] [148446] [INFO] Booting worker with pid: 148446
[2024-02-10 00:04:34 +0000] [148992] [INFO] Starting gunicorn 21.2.0
[2024-02-10 00:04:34 +0000] [148992] [ERROR] Connection in use: ('0.0.0.0', 8000)
[2024-02-10 00:04:34 +0000] [148992] [ERROR] Retrying in 1 second.
[2024-02-10 00:04:35 +0000] [148992] [ERROR] Connection in use: ('0.0.0.0', 8000)
[2024-02-10 00:04:35 +0000] [148992] [ERROR] Retrying in 1 second.
[2024-02-10 00:04:36 +0000] [148992] [ERROR] Connection in use: ('0.0.0.0', 8000)
[2024-02-10 00:04:36 +0000] [148992] [ERROR] Retrying in 1 second.
[2024-02-10 00:04:37 +0000] [148992] [ERROR] Connection in use: ('0.0.0.0', 8000)
[2024-02-10 00:04:37 +0000] [148992] [ERROR] Retrying in 1 second.
[2024-02-10 00:04:38 +0000] [148992] [ERROR] Connection in use: ('0.0.0.0', 8000)
[2024-02-10 00:04:38 +0000] [148992] [ERROR] Retrying in 1 second.
[2024-02-10 00:04:39 +0000] [148992] [ERROR] Can't connect to ('0.0.0.0', 8000)
[2024-02-10 00:05:13 +0000] [149559] [INFO] Starting gunicorn 21.2.0
[2024-02-10 00:05:13 +0000] [149559] [INFO] Listening at: http://0.0.0.0:8000 (149559)
[2024-02-10 00:05:13 +0000] [149559] [INFO] Using worker: sync
[2024-02-10 00:05:13 +0000] [149566] [INFO] Booting worker with pid: 149566
[2024-02-10 00:05:45 +0000] [150116] [INFO] Starting gunicorn 21.2.0
[2024-02-10 00:05:45 +0000] [150116] [ERROR] Connection in use: ('0.0.0.0', 8000)
[2024-02-10 00:05:45 +0000] [150116] [ERROR] Retrying in 1 second.
[2024-02-10 00:05:46 +0000] [150116] [ERROR] Connection in use: ('0.0.0.0', 8000)
[2024-02-10 00:05:46 +0000] [150116] [ERROR] Retrying in 1 second.
[2024-02-10 00:05:47 +0000] [150116] [ERROR] Connection in use: ('0.0.0.0', 8000)
[2024-02-10 00:05:47 +0000] [150116] [ERROR] Retrying in 1 second.
[2024-02-10 00:05:48 +0000] [150116] [ERROR] Connection in use: ('0.0.0.0', 8000)
[2024-02-10 00:05:48 +0000] [150116] [ERROR] Retrying in 1 second.
[2024-02-10 00:05:49 +0000] [150116] [ERROR] Connection in use: ('0.0.0.0', 8000)
[2024-02-10 00:05:49 +0000] [150116] [ERROR] Retrying in 1 second.
[2024-02-10 00:05:50 +0000] [150116] [ERROR] Can't connect to ('0.0.0.0', 8000)
[2024-02-10 00:06:18 +0000] [150681] [INFO] Starting gunicorn 21.2.0
[2024-02-10 00:06:18 +0000] [150681] [INFO] Listening at: http://0.0.0.0:8000 (150681)
[2024-02-10 00:06:18 +0000] [150681] [INFO] Using worker: sync
[2024-02-10 00:06:18 +0000] [150696] [INFO] Booting worker with pid: 150696
[2024-02-10 00:06:51 +0000] [151313] [INFO] Starting gunicorn 21.2.0
[2024-02-10 00:06:51 +0000] [151313] [INFO] Listening at: http://0.0.0.0:8000 (151313)
[2024-02-10 00:06:51 +0000] [151313] [INFO] Using worker: sync
[2024-02-10 00:06:51 +0000] [151314] [INFO] Booting worker with pid: 151314
[2024-02-10 00:07:38 +0000] [151972] [INFO] Starting gunicorn 21.2.0
[2024-02-10 00:07:38 +0000] [151972] [INFO] Listening at: http://0.0.0.0:8000 (151972)
[2024-02-10 00:07:38 +0000] [151972] [INFO] Using worker: sync
[2024-02-10 00:07:38 +0000] [151976] [INFO] Booting worker with pid: 151976
[2024-02-10 00:08:29 +0000] [152542] [INFO] Starting gunicorn 21.2.0
[2024-02-10 00:08:29 +0000] [152542] [INFO] Listening at: http://0.0.0.0:8000 (152542)
[2024-02-10 00:08:29 +0000] [152542] [INFO] Using worker: sync
[2024-02-10 00:08:29 +0000] [152543] [INFO] Booting worker with pid: 152543
[2024-02-10 00:09:10 +0000] [153114] [INFO] Starting gunicorn 21.2.0
[2024-02-10 00:09:10 +0000] [153114] [INFO] Listening at: http://0.0.0.0:8000 (153114)
[2024-02-10 00:09:10 +0000] [153114] [INFO] Using worker: sync
[2024-02-10 00:09:10 +0000] [153115] [INFO] Booting worker with pid: 153115
[2024-02-10 00:09:45 +0000] [153668] [INFO] Starting gunicorn 21.2.0
[2024-02-10 00:09:45 +0000] [153668] [INFO] Listening at: http://0.0.0.0:8000 (153668)
[2024-02-10 00:09:45 +0000] [153668] [INFO] Using worker: sync
[2024-02-10 00:09:45 +0000] [153669] [INFO] Booting worker with pid: 153669
[2024-02-10 00:10:16 +0000] [154228] [INFO] Starting gunicorn 21.2.0
[2024-02-10 00:10:16 +0000] [154228] [INFO] Listening at: http://0.0.0.0:8000 (154228)
[2024-02-10 00:10:16 +0000] [154228] [INFO] Using worker: sync
[2024-02-10 00:10:16 +0000] [154229] [INFO] Booting worker with pid: 154229
[2024-02-10 00:10:49 +0000] [154779] [INFO] Starting gunicorn 21.2.0
[2024-02-10 00:10:49 +0000] [154779] [INFO] Listening at: http://0.0.0.0:8000 (154779)
[2024-02-10 00:10:49 +0000] [154779] [INFO] Using worker: sync
[2024-02-10 00:10:49 +0000] [154780] [INFO] Booting worker with pid: 154780
[2024-02-10 00:11:23 +0000] [155342] [INFO] Starting gunicorn 21.2.0
[2024-02-10 00:11:23 +0000] [155342] [INFO] Listening at: http://0.0.0.0:8000 (155342)
[2024-02-10 00:11:23 +0000] [155342] [INFO] Using worker: sync
[2024-02-10 00:11:23 +0000] [155343] [INFO] Booting worker with pid: 155343
[2024-02-10 00:11:58 +0000] [155900] [INFO] Starting gunicorn 21.2.0
[2024-02-10 00:11:58 +0000] [155900] [INFO] Listening at: http://0.0.0.0:8000 (155900)
[2024-02-10 00:11:58 +0000] [155900] [INFO] Using worker: sync
[2024-02-10 00:11:58 +0000] [155901] [INFO] Booting worker with pid: 155901
[2024-02-10 00:12:31 +0000] [156458] [INFO] Starting gunicorn 21.2.0
[2024-02-10 00:12:31 +0000] [156458] [INFO] Listening at: http://0.0.0.0:8000 (156458)
[2024-02-10 00:12:31 +0000] [156458] [INFO] Using worker: sync
[2024-02-10 00:12:31 +0000] [156459] [INFO] Booting worker with pid: 156459
[2024-02-10 00:13:01 +0000] [157005] [INFO] Starting gunicorn 21.2.0
[2024-02-10 00:13:01 +0000] [157005] [INFO] Listening at: http://0.0.0.0:8000 (157005)
[2024-02-10 00:13:01 +0000] [157005] [INFO] Using worker: sync
[2024-02-10 00:13:01 +0000] [157006] [INFO] Booting worker with pid: 157006
[2024-02-10 00:13:28 +0000] [157527] [INFO] Starting gunicorn 21.2.0
[2024-02-10 00:13:28 +0000] [157527] [INFO] Listening at: http://0.0.0.0:8000 (157527)
[2024-02-10 00:13:28 +0000] [157527] [INFO] Using worker: sync
[2024-02-10 00:13:28 +0000] [157528] [INFO] Booting worker with pid: 157528
[2024-02-10 00:14:06 +0000] [158126] [INFO] Starting gunicorn 21.2.0
[2024-02-10 00:14:06 +0000] [158126] [INFO] Listening at: http://0.0.0.0:8000 (158126)
[2024-02-10 00:14:06 +0000] [158126] [INFO] Using worker: sync
[2024-02-10 00:14:06 +0000] [158127] [INFO] Booting worker with pid: 158127
[2024-02-10 00:14:42 +0000] [158715] [INFO] Starting gunicorn 21.2.0
[2024-02-10 00:14:42 +0000] [158715] [INFO] Listening at: http://0.0.0.0:8000 (158715)
[2024-02-10 00:14:42 +0000] [158715] [INFO] Using worker: sync
[2024-02-10 00:14:42 +0000] [158716] [INFO] Booting worker with pid: 158716
[2024-02-10 00:15:19 +0000] [159275] [INFO] Starting gunicorn 21.2.0
[2024-02-10 00:15:19 +0000] [159275] [INFO] Listening at: http://0.0.0.0:8000 (159275)
[2024-02-10 00:15:19 +0000] [159275] [INFO] Using worker: sync
[2024-02-10 00:15:19 +0000] [159277] [INFO] Booting worker with pid: 159277
[2024-02-10 00:15:52 +0000] [159832] [INFO] Starting gunicorn 21.2.0
[2024-02-10 00:15:52 +0000] [159832] [INFO] Listening at: http://0.0.0.0:8000 (159832)
[2024-02-10 00:15:52 +0000] [159832] [INFO] Using worker: sync
[2024-02-10 00:15:52 +0000] [159833] [INFO] Booting worker with pid: 159833
[2024-02-10 00:16:25 +0000] [160383] [INFO] Starting gunicorn 21.2.0
[2024-02-10 00:16:25 +0000] [160383] [INFO] Listening at: http://0.0.0.0:8000 (160383)
[2024-02-10 00:16:25 +0000] [160383] [INFO] Using worker: sync
[2024-02-10 00:16:25 +0000] [160384] [INFO] Booting worker with pid: 160384
[2024-02-10 00:16:53 +0000] [160934] [INFO] Starting gunicorn 21.2.0
[2024-02-10 00:16:53 +0000] [160934] [INFO] Listening at: http://0.0.0.0:8000 (160934)
[2024-02-10 00:16:53 +0000] [160934] [INFO] Using worker: sync
[2024-02-10 00:16:53 +0000] [160935] [INFO] Booting worker with pid: 160935
[2024-02-10 00:17:24 +0000] [161462] [INFO] Starting gunicorn 21.2.0
[2024-02-10 00:17:24 +0000] [161462] [INFO] Listening at: http://0.0.0.0:8000 (161462)
[2024-02-10 00:17:24 +0000] [161462] [INFO] Using worker: sync
[2024-02-10 00:17:24 +0000] [161463] [INFO] Booting worker with pid: 161463
[2024-02-10 00:18:02 +0000] [162045] [INFO] Starting gunicorn 21.2.0
[2024-02-10 00:18:02 +0000] [162045] [INFO] Listening at: http://0.0.0.0:8000 (162045)
[2024-02-10 00:18:02 +0000] [162045] [INFO] Using worker: sync
[2024-02-10 00:18:02 +0000] [162046] [INFO] Booting worker with pid: 162046
[2024-02-10 00:18:36 +0000] [162601] [INFO] Starting gunicorn 21.2.0
[2024-02-10 00:18:36 +0000] [162601] [INFO] Listening at: http://0.0.0.0:8000 (162601)
[2024-02-10 00:18:36 +0000] [162601] [INFO] Using worker: sync
[2024-02-10 00:18:36 +0000] [162613] [INFO] Booting worker with pid: 162613
[2024-02-10 00:19:12 +0000] [163161] [INFO] Starting gunicorn 21.2.0
[2024-02-10 00:19:12 +0000] [163161] [INFO] Listening at: http://0.0.0.0:8000 (163161)
[2024-02-10 00:19:12 +0000] [163161] [INFO] Using worker: sync
[2024-02-10 00:19:12 +0000] [163165] [INFO] Booting worker with pid: 163165
[2024-02-10 00:19:41 +0000] [163680] [INFO] Starting gunicorn 21.2.0
[2024-02-10 00:19:41 +0000] [163680] [INFO] Listening at: http://0.0.0.0:8000 (163680)
[2024-02-10 00:19:41 +0000] [163680] [INFO] Using worker: sync
[2024-02-10 00:19:41 +0000] [163681] [INFO] Booting worker with pid: 163681
[2024-02-10 00:20:15 +0000] [164239] [INFO] Starting gunicorn 21.2.0
[2024-02-10 00:20:15 +0000] [164239] [INFO] Listening at: http://0.0.0.0:8000 (164239)
[2024-02-10 00:20:15 +0000] [164239] [INFO] Using worker: sync
[2024-02-10 00:20:15 +0000] [164240] [INFO] Booting worker with pid: 164240
[2024-02-10 00:21:54 +0000] [165978] [INFO] Starting gunicorn 21.2.0
[2024-02-10 00:21:54 +0000] [165978] [INFO] Listening at: http://0.0.0.0:8000 (165978)
[2024-02-10 00:21:54 +0000] [165978] [INFO] Using worker: sync
[2024-02-10 00:21:54 +0000] [165979] [INFO] Booting worker with pid: 165979
[2024-02-10 00:23:22 +0000] [165978] [CRITICAL] WORKER TIMEOUT (pid:165979)
[2024-02-10 00:23:22 +0000] [165979] [INFO] Worker exiting (pid: 165979)
[2024-02-10 00:23:23 +0000] [165978] [ERROR] Worker (pid:165979) exited with code 1
[2024-02-10 00:23:23 +0000] [165978] [ERROR] Worker (pid:165979) exited with code 1.
[2024-02-10 00:23:23 +0000] [166742] [INFO] Booting worker with pid: 166742
[2024-02-10 00:24:36 +0000] [165978] [CRITICAL] WORKER TIMEOUT (pid:166742)
[2024-02-10 00:24:36 +0000] [166742] [INFO] Worker exiting (pid: 166742)
[2024-02-10 00:24:36 +0000] [165978] [ERROR] Worker (pid:166742) exited with code 1
[2024-02-10 00:24:36 +0000] [165978] [ERROR] Worker (pid:166742) exited with code 1.
[2024-02-10 00:24:36 +0000] [167430] [INFO] Booting worker with pid: 167430
[2024-02-10 00:25:24 +0000] [168254] [INFO] Starting gunicorn 21.2.0
[2024-02-10 00:25:24 +0000] [168254] [ERROR] Connection in use: ('0.0.0.0', 8000)
[2024-02-10 00:25:24 +0000] [168254] [ERROR] Retrying in 1 second.
[2024-02-10 00:25:25 +0000] [168254] [ERROR] Connection in use: ('0.0.0.0', 8000)
[2024-02-10 00:25:25 +0000] [168254] [ERROR] Retrying in 1 second.
[2024-02-10 00:25:26 +0000] [168254] [ERROR] Connection in use: ('0.0.0.0', 8000)
[2024-02-10 00:25:26 +0000] [168254] [ERROR] Retrying in 1 second.
[2024-02-10 00:25:27 +0000] [168254] [ERROR] Connection in use: ('0.0.0.0', 8000)
[2024-02-10 00:25:27 +0000] [168254] [ERROR] Retrying in 1 second.
[2024-02-10 00:25:28 +0000] [168254] [ERROR] Connection in use: ('0.0.0.0', 8000)
[2024-02-10 00:25:28 +0000] [168254] [ERROR] Retrying in 1 second.
[2024-02-10 00:25:29 +0000] [168254] [ERROR] Can't connect to ('0.0.0.0', 8000)
[2024-02-10 00:26:58 +0000] [169232] [INFO] Starting gunicorn 21.2.0
[2024-02-10 00:26:58 +0000] [169232] [INFO] Listening at: http://0.0.0.0:8000 (169232)
[2024-02-10 00:26:58 +0000] [169232] [INFO] Using worker: sync
[2024-02-10 00:26:58 +0000] [169233] [INFO] Booting worker with pid: 169233
[2024-02-10 00:27:42 +0000] [169889] [INFO] Starting gunicorn 21.2.0
[2024-02-10 00:27:42 +0000] [169889] [ERROR] Connection in use: ('0.0.0.0', 8000)
[2024-02-10 00:27:42 +0000] [169889] [ERROR] Retrying in 1 second.
[2024-02-10 00:27:43 +0000] [169889] [INFO] Listening at: http://0.0.0.0:8000 (169889)
[2024-02-10 00:27:43 +0000] [169889] [INFO] Using worker: sync
[2024-02-10 00:27:43 +0000] [169906] [INFO] Booting worker with pid: 169906
[2024-02-10 00:28:19 +0000] [169889] [CRITICAL] WORKER TIMEOUT (pid:169906)
[2024-02-10 00:28:19 +0000] [169906] [INFO] Worker exiting (pid: 169906)
[2024-02-10 00:28:20 +0000] [169889] [ERROR] Worker (pid:169906) exited with code 1
[2024-02-10 00:28:20 +0000] [169889] [ERROR] Worker (pid:169906) exited with code 1.
[2024-02-10 00:28:20 +0000] [170132] [INFO] Booting worker with pid: 170132
[2024-02-10 00:28:57 +0000] [170745] [INFO] Starting gunicorn 21.2.0
[2024-02-10 00:28:57 +0000] [170745] [INFO] Listening at: http://0.0.0.0:8000 (170745)
[2024-02-10 00:28:57 +0000] [170745] [INFO] Using worker: sync
[2024-02-10 00:28:57 +0000] [170747] [INFO] Booting worker with pid: 170747
[2024-02-10 00:29:27 +0000] [171330] [INFO] Starting gunicorn 21.2.0
[2024-02-10 00:29:27 +0000] [171330] [INFO] Listening at: http://0.0.0.0:8000 (171330)
[2024-02-10 00:29:27 +0000] [171330] [INFO] Using worker: sync
[2024-02-10 00:29:27 +0000] [171332] [INFO] Booting worker with pid: 171332
[2024-02-10 00:29:59 +0000] [171330] [CRITICAL] WORKER TIMEOUT (pid:171332)
[2024-02-10 00:29:59 +0000] [171332] [INFO] Worker exiting (pid: 171332)
[2024-02-10 00:29:59 +0000] [171330] [ERROR] Worker (pid:171332) exited with code 1
[2024-02-10 00:29:59 +0000] [171330] [ERROR] Worker (pid:171332) exited with code 1.
[2024-02-10 00:29:59 +0000] [171468] [INFO] Booting worker with pid: 171468
[2024-02-10 01:25:05 +0000] [171330] [CRITICAL] WORKER TIMEOUT (pid:171468)
[2024-02-10 01:25:05 +0000] [171468] [INFO] Worker exiting (pid: 171468)
[2024-02-10 01:25:05 +0000] [171330] [ERROR] Worker (pid:171468) exited with code 1
[2024-02-10 01:25:05 +0000] [171330] [ERROR] Worker (pid:171468) exited with code 1.
[2024-02-10 01:25:05 +0000] [173337] [INFO] Booting worker with pid: 173337
[2024-02-10 01:25:16 +0000] [173337] [INFO] Worker exiting (pid: 173337)
[2024-02-10 01:25:16 +0000] [171330] [INFO] Handling signal: term
[2024-02-10 01:25:16 +0000] [171330] [ERROR] Worker (pid:173337) was sent SIGTERM!
[2024-02-10 01:25:17 +0000] [171330] [INFO] Shutting down: Master
[2024-02-10 01:29:51 +0000] [2662] [INFO] Starting gunicorn 21.2.0
[2024-02-10 01:29:51 +0000] [2662] [INFO] Listening at: http://0.0.0.0:8000 (2662)
[2024-02-10 01:29:51 +0000] [2662] [INFO] Using worker: sync
[2024-02-10 01:29:51 +0000] [2664] [INFO] Booting worker with pid: 2664
[2024-02-10 01:30:47 +0000] [3385] [INFO] Starting gunicorn 21.2.0
[2024-02-10 01:30:47 +0000] [3385] [ERROR] Connection in use: ('0.0.0.0', 8000)
[2024-02-10 01:30:47 +0000] [3385] [ERROR] Retrying in 1 second.
[2024-02-10 01:30:48 +0000] [3385] [INFO] Listening at: http://0.0.0.0:8000 (3385)
[2024-02-10 01:30:48 +0000] [3385] [INFO] Using worker: sync
[2024-02-10 01:30:48 +0000] [3394] [INFO] Booting worker with pid: 3394
[2024-02-10 01:31:19 +0000] [3385] [CRITICAL] WORKER TIMEOUT (pid:3394)
[2024-02-10 01:31:19 +0000] [3394] [INFO] Worker exiting (pid: 3394)
[2024-02-10 01:31:19 +0000] [3385] [ERROR] Worker (pid:3394) exited with code 1
[2024-02-10 01:31:19 +0000] [3385] [ERROR] Worker (pid:3394) exited with code 1.
[2024-02-10 01:31:19 +0000] [3545] [INFO] Booting worker with pid: 3545
[2024-02-10 01:31:50 +0000] [3385] [CRITICAL] WORKER TIMEOUT (pid:3545)
[2024-02-10 01:31:50 +0000] [3545] [INFO] Worker exiting (pid: 3545)
[2024-02-10 01:31:50 +0000] [3385] [ERROR] Worker (pid:3545) exited with code 1
[2024-02-10 01:31:50 +0000] [3385] [ERROR] Worker (pid:3545) exited with code 1.
[2024-02-10 01:31:50 +0000] [3618] [INFO] Booting worker with pid: 3618
[2024-02-10 01:33:30 +0000] [3385] [CRITICAL] WORKER TIMEOUT (pid:3618)
[2024-02-10 01:33:30 +0000] [3618] [INFO] Worker exiting (pid: 3618)
[2024-02-10 01:33:30 +0000] [3385] [ERROR] Worker (pid:3618) exited with code 1
[2024-02-10 01:33:30 +0000] [3385] [ERROR] Worker (pid:3618) exited with code 1.
[2024-02-10 01:33:30 +0000] [3694] [INFO] Booting worker with pid: 3694
[2024-02-10 01:42:14 +0000] [6636] [INFO] Starting gunicorn 21.2.0
[2024-02-10 01:42:14 +0000] [6636] [ERROR] Connection in use: ('0.0.0.0', 8000)
[2024-02-10 01:42:14 +0000] [6636] [ERROR] Retrying in 1 second.
[2024-02-10 01:42:15 +0000] [6636] [ERROR] Connection in use: ('0.0.0.0', 8000)
[2024-02-10 01:42:15 +0000] [6636] [ERROR] Retrying in 1 second.
[2024-02-10 01:42:16 +0000] [6636] [ERROR] Connection in use: ('0.0.0.0', 8000)
[2024-02-10 01:42:16 +0000] [6636] [ERROR] Retrying in 1 second.
[2024-02-10 01:42:17 +0000] [6636] [ERROR] Connection in use: ('0.0.0.0', 8000)
[2024-02-10 01:42:17 +0000] [6636] [ERROR] Retrying in 1 second.
[2024-02-10 01:42:18 +0000] [6636] [ERROR] Connection in use: ('0.0.0.0', 8000)
[2024-02-10 01:42:18 +0000] [6636] [ERROR] Retrying in 1 second.
[2024-02-10 01:42:19 +0000] [6636] [ERROR] Can't connect to ('0.0.0.0', 8000)
[2024-02-10 01:43:03 +0000] [7329] [INFO] Starting gunicorn 21.2.0
[2024-02-10 01:43:03 +0000] [7329] [INFO] Listening at: http://0.0.0.0:8000 (7329)
[2024-02-10 01:43:03 +0000] [7329] [INFO] Using worker: sync
[2024-02-10 01:43:03 +0000] [7330] [INFO] Booting worker with pid: 7330
[2024-02-10 01:43:38 +0000] [7329] [CRITICAL] WORKER TIMEOUT (pid:7330)
[2024-02-10 01:43:38 +0000] [7330] [INFO] Worker exiting (pid: 7330)
[2024-02-10 01:43:39 +0000] [7329] [ERROR] Worker (pid:7330) exited with code 1
[2024-02-10 01:43:39 +0000] [7329] [ERROR] Worker (pid:7330) exited with code 1.
[2024-02-10 01:43:39 +0000] [7525] [INFO] Booting worker with pid: 7525
[2024-02-10 01:43:39,448] ERROR in app: Exception on /register [POST]
Traceback (most recent call last):
  File "/srv/talknet/backend/auth-service/venv/lib/python3.10/site-packages/sqlalchemy/engine/base.py", line 1969, in _exec_single_context
    self.dialect.do_execute(
  File "/srv/talknet/backend/auth-service/venv/lib/python3.10/site-packages/sqlalchemy/engine/default.py", line 922, in do_execute
    cursor.execute(statement, parameters)
sqlite3.OperationalError: no such table: user

The above exception was the direct cause of the following exception:

Traceback (most recent call last):
  File "/srv/talknet/backend/auth-service/venv/lib/python3.10/site-packages/flask/app.py", line 1463, in wsgi_app
    response = self.full_dispatch_request()
  File "/srv/talknet/backend/auth-service/venv/lib/python3.10/site-packages/flask/app.py", line 872, in full_dispatch_request
    rv = self.handle_user_exception(e)
  File "/srv/talknet/backend/auth-service/venv/lib/python3.10/site-packages/flask_cors/extension.py", line 176, in wrapped_function
    return cors_after_request(app.make_response(f(*args, **kwargs)))
  File "/srv/talknet/backend/auth-service/venv/lib/python3.10/site-packages/flask/app.py", line 870, in full_dispatch_request
    rv = self.dispatch_request()
  File "/srv/talknet/backend/auth-service/venv/lib/python3.10/site-packages/flask/app.py", line 855, in dispatch_request
    return self.ensure_sync(self.view_functions[rule.endpoint])(**view_args)  # type: ignore[no-any-return]
  File "/srv/talknet/backend/auth-service/app.py", line 38, in register
    user = User.query.filter_by(email=data['email']).first()
  File "/srv/talknet/backend/auth-service/venv/lib/python3.10/site-packages/sqlalchemy/orm/query.py", line 2748, in first
    return self.limit(1)._iter().first()  # type: ignore
  File "/srv/talknet/backend/auth-service/venv/lib/python3.10/site-packages/sqlalchemy/orm/query.py", line 2847, in _iter
    result: Union[ScalarResult[_T], Result[_T]] = self.session.execute(
  File "/srv/talknet/backend/auth-service/venv/lib/python3.10/site-packages/sqlalchemy/orm/session.py", line 2308, in execute
    return self._execute_internal(
  File "/srv/talknet/backend/auth-service/venv/lib/python3.10/site-packages/sqlalchemy/orm/session.py", line 2190, in _execute_internal
    result: Result[Any] = compile_state_cls.orm_execute_statement(
  File "/srv/talknet/backend/auth-service/venv/lib/python3.10/site-packages/sqlalchemy/orm/context.py", line 293, in orm_execute_statement
    result = conn.execute(
  File "/srv/talknet/backend/auth-service/venv/lib/python3.10/site-packages/sqlalchemy/engine/base.py", line 1416, in execute
    return meth(
  File "/srv/talknet/backend/auth-service/venv/lib/python3.10/site-packages/sqlalchemy/sql/elements.py", line 517, in _execute_on_connection
    return connection._execute_clauseelement(
  File "/srv/talknet/backend/auth-service/venv/lib/python3.10/site-packages/sqlalchemy/engine/base.py", line 1639, in _execute_clauseelement
    ret = self._execute_context(
  File "/srv/talknet/backend/auth-service/venv/lib/python3.10/site-packages/sqlalchemy/engine/base.py", line 1848, in _execute_context
    return self._exec_single_context(
  File "/srv/talknet/backend/auth-service/venv/lib/python3.10/site-packages/sqlalchemy/engine/base.py", line 1988, in _exec_single_context
    self._handle_dbapi_exception(
  File "/srv/talknet/backend/auth-service/venv/lib/python3.10/site-packages/sqlalchemy/engine/base.py", line 2344, in _handle_dbapi_exception
    raise sqlalchemy_exception.with_traceback(exc_info[2]) from e
  File "/srv/talknet/backend/auth-service/venv/lib/python3.10/site-packages/sqlalchemy/engine/base.py", line 1969, in _exec_single_context
    self.dialect.do_execute(
  File "/srv/talknet/backend/auth-service/venv/lib/python3.10/site-packages/sqlalchemy/engine/default.py", line 922, in do_execute
    cursor.execute(statement, parameters)
sqlalchemy.exc.OperationalError: (sqlite3.OperationalError) no such table: user
[SQL: SELECT user.id AS user_id, user.username AS user_username, user.email AS user_email, user.password AS user_password 
FROM user 
WHERE user.email = ?
 LIMIT ? OFFSET ?]
[parameters: ('mykytashch@hotmail.com', 1, 0)]
(Background on this error at: https://sqlalche.me/e/20/e3q8)
[2024-02-10 01:43:39,457] ERROR in app: Exception on /register [POST]
Traceback (most recent call last):
  File "/srv/talknet/backend/auth-service/venv/lib/python3.10/site-packages/sqlalchemy/engine/base.py", line 1969, in _exec_single_context
    self.dialect.do_execute(
  File "/srv/talknet/backend/auth-service/venv/lib/python3.10/site-packages/sqlalchemy/engine/default.py", line 922, in do_execute
    cursor.execute(statement, parameters)
sqlite3.OperationalError: no such table: user

The above exception was the direct cause of the following exception:

Traceback (most recent call last):
  File "/srv/talknet/backend/auth-service/venv/lib/python3.10/site-packages/flask/app.py", line 1463, in wsgi_app
    response = self.full_dispatch_request()
  File "/srv/talknet/backend/auth-service/venv/lib/python3.10/site-packages/flask/app.py", line 872, in full_dispatch_request
    rv = self.handle_user_exception(e)
  File "/srv/talknet/backend/auth-service/venv/lib/python3.10/site-packages/flask_cors/extension.py", line 176, in wrapped_function
    return cors_after_request(app.make_response(f(*args, **kwargs)))
  File "/srv/talknet/backend/auth-service/venv/lib/python3.10/site-packages/flask/app.py", line 870, in full_dispatch_request
    rv = self.dispatch_request()
  File "/srv/talknet/backend/auth-service/venv/lib/python3.10/site-packages/flask/app.py", line 855, in dispatch_request
    return self.ensure_sync(self.view_functions[rule.endpoint])(**view_args)  # type: ignore[no-any-return]
  File "/srv/talknet/backend/auth-service/app.py", line 38, in register
    user = User.query.filter_by(email=data['email']).first()
  File "/srv/talknet/backend/auth-service/venv/lib/python3.10/site-packages/sqlalchemy/orm/query.py", line 2748, in first
    return self.limit(1)._iter().first()  # type: ignore
  File "/srv/talknet/backend/auth-service/venv/lib/python3.10/site-packages/sqlalchemy/orm/query.py", line 2847, in _iter
    result: Union[ScalarResult[_T], Result[_T]] = self.session.execute(
  File "/srv/talknet/backend/auth-service/venv/lib/python3.10/site-packages/sqlalchemy/orm/session.py", line 2308, in execute
    return self._execute_internal(
  File "/srv/talknet/backend/auth-service/venv/lib/python3.10/site-packages/sqlalchemy/orm/session.py", line 2190, in _execute_internal
    result: Result[Any] = compile_state_cls.orm_execute_statement(
  File "/srv/talknet/backend/auth-service/venv/lib/python3.10/site-packages/sqlalchemy/orm/context.py", line 293, in orm_execute_statement
    result = conn.execute(
  File "/srv/talknet/backend/auth-service/venv/lib/python3.10/site-packages/sqlalchemy/engine/base.py", line 1416, in execute
    return meth(
  File "/srv/talknet/backend/auth-service/venv/lib/python3.10/site-packages/sqlalchemy/sql/elements.py", line 517, in _execute_on_connection
    return connection._execute_clauseelement(
  File "/srv/talknet/backend/auth-service/venv/lib/python3.10/site-packages/sqlalchemy/engine/base.py", line 1639, in _execute_clauseelement
    ret = self._execute_context(
  File "/srv/talknet/backend/auth-service/venv/lib/python3.10/site-packages/sqlalchemy/engine/base.py", line 1848, in _execute_context
    return self._exec_single_context(
  File "/srv/talknet/backend/auth-service/venv/lib/python3.10/site-packages/sqlalchemy/engine/base.py", line 1988, in _exec_single_context
    self._handle_dbapi_exception(
  File "/srv/talknet/backend/auth-service/venv/lib/python3.10/site-packages/sqlalchemy/engine/base.py", line 2344, in _handle_dbapi_exception
    raise sqlalchemy_exception.with_traceback(exc_info[2]) from e
  File "/srv/talknet/backend/auth-service/venv/lib/python3.10/site-packages/sqlalchemy/engine/base.py", line 1969, in _exec_single_context
    self.dialect.do_execute(
  File "/srv/talknet/backend/auth-service/venv/lib/python3.10/site-packages/sqlalchemy/engine/default.py", line 922, in do_execute
    cursor.execute(statement, parameters)
sqlalchemy.exc.OperationalError: (sqlite3.OperationalError) no such table: user
[SQL: SELECT user.id AS user_id, user.username AS user_username, user.email AS user_email, user.password AS user_password 
FROM user 
WHERE user.email = ?
 LIMIT ? OFFSET ?]
[parameters: ('mykytashch@hotmail.com', 1, 0)]
(Background on this error at: https://sqlalche.me/e/20/e3q8)
[2024-02-10 01:43:39,460] ERROR in app: Exception on /register [POST]
Traceback (most recent call last):
  File "/srv/talknet/backend/auth-service/venv/lib/python3.10/site-packages/sqlalchemy/engine/base.py", line 1969, in _exec_single_context
    self.dialect.do_execute(
  File "/srv/talknet/backend/auth-service/venv/lib/python3.10/site-packages/sqlalchemy/engine/default.py", line 922, in do_execute
    cursor.execute(statement, parameters)
sqlite3.OperationalError: no such table: user

The above exception was the direct cause of the following exception:

Traceback (most recent call last):
  File "/srv/talknet/backend/auth-service/venv/lib/python3.10/site-packages/flask/app.py", line 1463, in wsgi_app
    response = self.full_dispatch_request()
  File "/srv/talknet/backend/auth-service/venv/lib/python3.10/site-packages/flask/app.py", line 872, in full_dispatch_request
    rv = self.handle_user_exception(e)
  File "/srv/talknet/backend/auth-service/venv/lib/python3.10/site-packages/flask_cors/extension.py", line 176, in wrapped_function
    return cors_after_request(app.make_response(f(*args, **kwargs)))
  File "/srv/talknet/backend/auth-service/venv/lib/python3.10/site-packages/flask/app.py", line 870, in full_dispatch_request
    rv = self.dispatch_request()
  File "/srv/talknet/backend/auth-service/venv/lib/python3.10/site-packages/flask/app.py", line 855, in dispatch_request
    return self.ensure_sync(self.view_functions[rule.endpoint])(**view_args)  # type: ignore[no-any-return]
  File "/srv/talknet/backend/auth-service/app.py", line 38, in register
    user = User.query.filter_by(email=data['email']).first()
  File "/srv/talknet/backend/auth-service/venv/lib/python3.10/site-packages/sqlalchemy/orm/query.py", line 2748, in first
    return self.limit(1)._iter().first()  # type: ignore
  File "/srv/talknet/backend/auth-service/venv/lib/python3.10/site-packages/sqlalchemy/orm/query.py", line 2847, in _iter
    result: Union[ScalarResult[_T], Result[_T]] = self.session.execute(
  File "/srv/talknet/backend/auth-service/venv/lib/python3.10/site-packages/sqlalchemy/orm/session.py", line 2308, in execute
    return self._execute_internal(
  File "/srv/talknet/backend/auth-service/venv/lib/python3.10/site-packages/sqlalchemy/orm/session.py", line 2190, in _execute_internal
    result: Result[Any] = compile_state_cls.orm_execute_statement(
  File "/srv/talknet/backend/auth-service/venv/lib/python3.10/site-packages/sqlalchemy/orm/context.py", line 293, in orm_execute_statement
    result = conn.execute(
  File "/srv/talknet/backend/auth-service/venv/lib/python3.10/site-packages/sqlalchemy/engine/base.py", line 1416, in execute
    return meth(
  File "/srv/talknet/backend/auth-service/venv/lib/python3.10/site-packages/sqlalchemy/sql/elements.py", line 517, in _execute_on_connection
    return connection._execute_clauseelement(
  File "/srv/talknet/backend/auth-service/venv/lib/python3.10/site-packages/sqlalchemy/engine/base.py", line 1639, in _execute_clauseelement
    ret = self._execute_context(
  File "/srv/talknet/backend/auth-service/venv/lib/python3.10/site-packages/sqlalchemy/engine/base.py", line 1848, in _execute_context
    return self._exec_single_context(
  File "/srv/talknet/backend/auth-service/venv/lib/python3.10/site-packages/sqlalchemy/engine/base.py", line 1988, in _exec_single_context
    self._handle_dbapi_exception(
  File "/srv/talknet/backend/auth-service/venv/lib/python3.10/site-packages/sqlalchemy/engine/base.py", line 2344, in _handle_dbapi_exception
    raise sqlalchemy_exception.with_traceback(exc_info[2]) from e
  File "/srv/talknet/backend/auth-service/venv/lib/python3.10/site-packages/sqlalchemy/engine/base.py", line 1969, in _exec_single_context
    self.dialect.do_execute(
  File "/srv/talknet/backend/auth-service/venv/lib/python3.10/site-packages/sqlalchemy/engine/default.py", line 922, in do_execute
    cursor.execute(statement, parameters)
sqlalchemy.exc.OperationalError: (sqlite3.OperationalError) no such table: user
[SQL: SELECT user.id AS user_id, user.username AS user_username, user.email AS user_email, user.password AS user_password 
FROM user 
WHERE user.email = ?
 LIMIT ? OFFSET ?]
[parameters: ('mykytashch@hotmail.com', 1, 0)]
(Background on this error at: https://sqlalche.me/e/20/e3q8)
[2024-02-10 01:43:39,462] ERROR in app: Exception on /register [POST]
Traceback (most recent call last):
  File "/srv/talknet/backend/auth-service/venv/lib/python3.10/site-packages/sqlalchemy/engine/base.py", line 1969, in _exec_single_context
    self.dialect.do_execute(
  File "/srv/talknet/backend/auth-service/venv/lib/python3.10/site-packages/sqlalchemy/engine/default.py", line 922, in do_execute
    cursor.execute(statement, parameters)
sqlite3.OperationalError: no such table: user

The above exception was the direct cause of the following exception:

Traceback (most recent call last):
  File "/srv/talknet/backend/auth-service/venv/lib/python3.10/site-packages/flask/app.py", line 1463, in wsgi_app
    response = self.full_dispatch_request()
  File "/srv/talknet/backend/auth-service/venv/lib/python3.10/site-packages/flask/app.py", line 872, in full_dispatch_request
    rv = self.handle_user_exception(e)
  File "/srv/talknet/backend/auth-service/venv/lib/python3.10/site-packages/flask_cors/extension.py", line 176, in wrapped_function
    return cors_after_request(app.make_response(f(*args, **kwargs)))
  File "/srv/talknet/backend/auth-service/venv/lib/python3.10/site-packages/flask/app.py", line 870, in full_dispatch_request
    rv = self.dispatch_request()
  File "/srv/talknet/backend/auth-service/venv/lib/python3.10/site-packages/flask/app.py", line 855, in dispatch_request
    return self.ensure_sync(self.view_functions[rule.endpoint])(**view_args)  # type: ignore[no-any-return]
  File "/srv/talknet/backend/auth-service/app.py", line 38, in register
    user = User.query.filter_by(email=data['email']).first()
  File "/srv/talknet/backend/auth-service/venv/lib/python3.10/site-packages/sqlalchemy/orm/query.py", line 2748, in first
    return self.limit(1)._iter().first()  # type: ignore
  File "/srv/talknet/backend/auth-service/venv/lib/python3.10/site-packages/sqlalchemy/orm/query.py", line 2847, in _iter
    result: Union[ScalarResult[_T], Result[_T]] = self.session.execute(
  File "/srv/talknet/backend/auth-service/venv/lib/python3.10/site-packages/sqlalchemy/orm/session.py", line 2308, in execute
    return self._execute_internal(
  File "/srv/talknet/backend/auth-service/venv/lib/python3.10/site-packages/sqlalchemy/orm/session.py", line 2190, in _execute_internal
    result: Result[Any] = compile_state_cls.orm_execute_statement(
  File "/srv/talknet/backend/auth-service/venv/lib/python3.10/site-packages/sqlalchemy/orm/context.py", line 293, in orm_execute_statement
    result = conn.execute(
  File "/srv/talknet/backend/auth-service/venv/lib/python3.10/site-packages/sqlalchemy/engine/base.py", line 1416, in execute
    return meth(
  File "/srv/talknet/backend/auth-service/venv/lib/python3.10/site-packages/sqlalchemy/sql/elements.py", line 517, in _execute_on_connection
    return connection._execute_clauseelement(
  File "/srv/talknet/backend/auth-service/venv/lib/python3.10/site-packages/sqlalchemy/engine/base.py", line 1639, in _execute_clauseelement
    ret = self._execute_context(
  File "/srv/talknet/backend/auth-service/venv/lib/python3.10/site-packages/sqlalchemy/engine/base.py", line 1848, in _execute_context
    return self._exec_single_context(
  File "/srv/talknet/backend/auth-service/venv/lib/python3.10/site-packages/sqlalchemy/engine/base.py", line 1988, in _exec_single_context
    self._handle_dbapi_exception(
  File "/srv/talknet/backend/auth-service/venv/lib/python3.10/site-packages/sqlalchemy/engine/base.py", line 2344, in _handle_dbapi_exception
    raise sqlalchemy_exception.with_traceback(exc_info[2]) from e
  File "/srv/talknet/backend/auth-service/venv/lib/python3.10/site-packages/sqlalchemy/engine/base.py", line 1969, in _exec_single_context
    self.dialect.do_execute(
  File "/srv/talknet/backend/auth-service/venv/lib/python3.10/site-packages/sqlalchemy/engine/default.py", line 922, in do_execute
    cursor.execute(statement, parameters)
sqlalchemy.exc.OperationalError: (sqlite3.OperationalError) no such table: user
[SQL: SELECT user.id AS user_id, user.username AS user_username, user.email AS user_email, user.password AS user_password 
FROM user 
WHERE user.email = ?
 LIMIT ? OFFSET ?]
[parameters: ('mykytashch@hotmail.com', 1, 0)]
(Background on this error at: https://sqlalche.me/e/20/e3q8)
[2024-02-10 01:43:39,470] ERROR in app: Exception on /register [POST]
Traceback (most recent call last):
  File "/srv/talknet/backend/auth-service/venv/lib/python3.10/site-packages/sqlalchemy/engine/base.py", line 1969, in _exec_single_context
    self.dialect.do_execute(
  File "/srv/talknet/backend/auth-service/venv/lib/python3.10/site-packages/sqlalchemy/engine/default.py", line 922, in do_execute
    cursor.execute(statement, parameters)
sqlite3.OperationalError: no such table: user

The above exception was the direct cause of the following exception:

Traceback (most recent call last):
  File "/srv/talknet/backend/auth-service/venv/lib/python3.10/site-packages/flask/app.py", line 1463, in wsgi_app
    response = self.full_dispatch_request()
  File "/srv/talknet/backend/auth-service/venv/lib/python3.10/site-packages/flask/app.py", line 872, in full_dispatch_request
    rv = self.handle_user_exception(e)
  File "/srv/talknet/backend/auth-service/venv/lib/python3.10/site-packages/flask_cors/extension.py", line 176, in wrapped_function
    return cors_after_request(app.make_response(f(*args, **kwargs)))
  File "/srv/talknet/backend/auth-service/venv/lib/python3.10/site-packages/flask/app.py", line 870, in full_dispatch_request
    rv = self.dispatch_request()
  File "/srv/talknet/backend/auth-service/venv/lib/python3.10/site-packages/flask/app.py", line 855, in dispatch_request
    return self.ensure_sync(self.view_functions[rule.endpoint])(**view_args)  # type: ignore[no-any-return]
  File "/srv/talknet/backend/auth-service/app.py", line 38, in register
    user = User.query.filter_by(email=data['email']).first()
  File "/srv/talknet/backend/auth-service/venv/lib/python3.10/site-packages/sqlalchemy/orm/query.py", line 2748, in first
    return self.limit(1)._iter().first()  # type: ignore
  File "/srv/talknet/backend/auth-service/venv/lib/python3.10/site-packages/sqlalchemy/orm/query.py", line 2847, in _iter
    result: Union[ScalarResult[_T], Result[_T]] = self.session.execute(
  File "/srv/talknet/backend/auth-service/venv/lib/python3.10/site-packages/sqlalchemy/orm/session.py", line 2308, in execute
    return self._execute_internal(
  File "/srv/talknet/backend/auth-service/venv/lib/python3.10/site-packages/sqlalchemy/orm/session.py", line 2190, in _execute_internal
    result: Result[Any] = compile_state_cls.orm_execute_statement(
  File "/srv/talknet/backend/auth-service/venv/lib/python3.10/site-packages/sqlalchemy/orm/context.py", line 293, in orm_execute_statement
    result = conn.execute(
  File "/srv/talknet/backend/auth-service/venv/lib/python3.10/site-packages/sqlalchemy/engine/base.py", line 1416, in execute
    return meth(
  File "/srv/talknet/backend/auth-service/venv/lib/python3.10/site-packages/sqlalchemy/sql/elements.py", line 517, in _execute_on_connection
    return connection._execute_clauseelement(
  File "/srv/talknet/backend/auth-service/venv/lib/python3.10/site-packages/sqlalchemy/engine/base.py", line 1639, in _execute_clauseelement
    ret = self._execute_context(
  File "/srv/talknet/backend/auth-service/venv/lib/python3.10/site-packages/sqlalchemy/engine/base.py", line 1848, in _execute_context
    return self._exec_single_context(
  File "/srv/talknet/backend/auth-service/venv/lib/python3.10/site-packages/sqlalchemy/engine/base.py", line 1988, in _exec_single_context
    self._handle_dbapi_exception(
  File "/srv/talknet/backend/auth-service/venv/lib/python3.10/site-packages/sqlalchemy/engine/base.py", line 2344, in _handle_dbapi_exception
    raise sqlalchemy_exception.with_traceback(exc_info[2]) from e
  File "/srv/talknet/backend/auth-service/venv/lib/python3.10/site-packages/sqlalchemy/engine/base.py", line 1969, in _exec_single_context
    self.dialect.do_execute(
  File "/srv/talknet/backend/auth-service/venv/lib/python3.10/site-packages/sqlalchemy/engine/default.py", line 922, in do_execute
    cursor.execute(statement, parameters)
sqlalchemy.exc.OperationalError: (sqlite3.OperationalError) no such table: user
[SQL: SELECT user.id AS user_id, user.username AS user_username, user.email AS user_email, user.password AS user_password 
FROM user 
WHERE user.email = ?
 LIMIT ? OFFSET ?]
[parameters: ('mykytashch@hotmail.com', 1, 0)]
(Background on this error at: https://sqlalche.me/e/20/e3q8)
[2024-02-10 01:43:39,472] ERROR in app: Exception on /register [POST]
Traceback (most recent call last):
  File "/srv/talknet/backend/auth-service/venv/lib/python3.10/site-packages/sqlalchemy/engine/base.py", line 1969, in _exec_single_context
    self.dialect.do_execute(
  File "/srv/talknet/backend/auth-service/venv/lib/python3.10/site-packages/sqlalchemy/engine/default.py", line 922, in do_execute
    cursor.execute(statement, parameters)
sqlite3.OperationalError: no such table: user

The above exception was the direct cause of the following exception:

Traceback (most recent call last):
  File "/srv/talknet/backend/auth-service/venv/lib/python3.10/site-packages/flask/app.py", line 1463, in wsgi_app
    response = self.full_dispatch_request()
  File "/srv/talknet/backend/auth-service/venv/lib/python3.10/site-packages/flask/app.py", line 872, in full_dispatch_request
    rv = self.handle_user_exception(e)
  File "/srv/talknet/backend/auth-service/venv/lib/python3.10/site-packages/flask_cors/extension.py", line 176, in wrapped_function
    return cors_after_request(app.make_response(f(*args, **kwargs)))
  File "/srv/talknet/backend/auth-service/venv/lib/python3.10/site-packages/flask/app.py", line 870, in full_dispatch_request
    rv = self.dispatch_request()
  File "/srv/talknet/backend/auth-service/venv/lib/python3.10/site-packages/flask/app.py", line 855, in dispatch_request
    return self.ensure_sync(self.view_functions[rule.endpoint])(**view_args)  # type: ignore[no-any-return]
  File "/srv/talknet/backend/auth-service/app.py", line 38, in register
    user = User.query.filter_by(email=data['email']).first()
  File "/srv/talknet/backend/auth-service/venv/lib/python3.10/site-packages/sqlalchemy/orm/query.py", line 2748, in first
    return self.limit(1)._iter().first()  # type: ignore
  File "/srv/talknet/backend/auth-service/venv/lib/python3.10/site-packages/sqlalchemy/orm/query.py", line 2847, in _iter
    result: Union[ScalarResult[_T], Result[_T]] = self.session.execute(
  File "/srv/talknet/backend/auth-service/venv/lib/python3.10/site-packages/sqlalchemy/orm/session.py", line 2308, in execute
    return self._execute_internal(
  File "/srv/talknet/backend/auth-service/venv/lib/python3.10/site-packages/sqlalchemy/orm/session.py", line 2190, in _execute_internal
    result: Result[Any] = compile_state_cls.orm_execute_statement(
  File "/srv/talknet/backend/auth-service/venv/lib/python3.10/site-packages/sqlalchemy/orm/context.py", line 293, in orm_execute_statement
    result = conn.execute(
  File "/srv/talknet/backend/auth-service/venv/lib/python3.10/site-packages/sqlalchemy/engine/base.py", line 1416, in execute
    return meth(
  File "/srv/talknet/backend/auth-service/venv/lib/python3.10/site-packages/sqlalchemy/sql/elements.py", line 517, in _execute_on_connection
    return connection._execute_clauseelement(
  File "/srv/talknet/backend/auth-service/venv/lib/python3.10/site-packages/sqlalchemy/engine/base.py", line 1639, in _execute_clauseelement
    ret = self._execute_context(
  File "/srv/talknet/backend/auth-service/venv/lib/python3.10/site-packages/sqlalchemy/engine/base.py", line 1848, in _execute_context
    return self._exec_single_context(
  File "/srv/talknet/backend/auth-service/venv/lib/python3.10/site-packages/sqlalchemy/engine/base.py", line 1988, in _exec_single_context
    self._handle_dbapi_exception(
  File "/srv/talknet/backend/auth-service/venv/lib/python3.10/site-packages/sqlalchemy/engine/base.py", line 2344, in _handle_dbapi_exception
    raise sqlalchemy_exception.with_traceback(exc_info[2]) from e
  File "/srv/talknet/backend/auth-service/venv/lib/python3.10/site-packages/sqlalchemy/engine/base.py", line 1969, in _exec_single_context
    self.dialect.do_execute(
  File "/srv/talknet/backend/auth-service/venv/lib/python3.10/site-packages/sqlalchemy/engine/default.py", line 922, in do_execute
    cursor.execute(statement, parameters)
sqlalchemy.exc.OperationalError: (sqlite3.OperationalError) no such table: user
[SQL: SELECT user.id AS user_id, user.username AS user_username, user.email AS user_email, user.password AS user_password 
FROM user 
WHERE user.email = ?
 LIMIT ? OFFSET ?]
[parameters: ('mykytashch@hotmail.com', 1, 0)]
(Background on this error at: https://sqlalche.me/e/20/e3q8)
[2024-02-10 01:43:39,481] ERROR in app: Exception on /login [POST]
Traceback (most recent call last):
  File "/srv/talknet/backend/auth-service/venv/lib/python3.10/site-packages/sqlalchemy/engine/base.py", line 1969, in _exec_single_context
    self.dialect.do_execute(
  File "/srv/talknet/backend/auth-service/venv/lib/python3.10/site-packages/sqlalchemy/engine/default.py", line 922, in do_execute
    cursor.execute(statement, parameters)
sqlite3.OperationalError: no such table: user

The above exception was the direct cause of the following exception:

Traceback (most recent call last):
  File "/srv/talknet/backend/auth-service/venv/lib/python3.10/site-packages/flask/app.py", line 1463, in wsgi_app
    response = self.full_dispatch_request()
  File "/srv/talknet/backend/auth-service/venv/lib/python3.10/site-packages/flask/app.py", line 872, in full_dispatch_request
    rv = self.handle_user_exception(e)
  File "/srv/talknet/backend/auth-service/venv/lib/python3.10/site-packages/flask_cors/extension.py", line 176, in wrapped_function
    return cors_after_request(app.make_response(f(*args, **kwargs)))
  File "/srv/talknet/backend/auth-service/venv/lib/python3.10/site-packages/flask/app.py", line 870, in full_dispatch_request
    rv = self.dispatch_request()
  File "/srv/talknet/backend/auth-service/venv/lib/python3.10/site-packages/flask/app.py", line 855, in dispatch_request
    return self.ensure_sync(self.view_functions[rule.endpoint])(**view_args)  # type: ignore[no-any-return]
  File "/srv/talknet/backend/auth-service/app.py", line 50, in login
    user = User.query.filter_by(email=data['email']).first()
  File "/srv/talknet/backend/auth-service/venv/lib/python3.10/site-packages/sqlalchemy/orm/query.py", line 2748, in first
    return self.limit(1)._iter().first()  # type: ignore
  File "/srv/talknet/backend/auth-service/venv/lib/python3.10/site-packages/sqlalchemy/orm/query.py", line 2847, in _iter
    result: Union[ScalarResult[_T], Result[_T]] = self.session.execute(
  File "/srv/talknet/backend/auth-service/venv/lib/python3.10/site-packages/sqlalchemy/orm/session.py", line 2308, in execute
    return self._execute_internal(
  File "/srv/talknet/backend/auth-service/venv/lib/python3.10/site-packages/sqlalchemy/orm/session.py", line 2190, in _execute_internal
    result: Result[Any] = compile_state_cls.orm_execute_statement(
  File "/srv/talknet/backend/auth-service/venv/lib/python3.10/site-packages/sqlalchemy/orm/context.py", line 293, in orm_execute_statement
    result = conn.execute(
  File "/srv/talknet/backend/auth-service/venv/lib/python3.10/site-packages/sqlalchemy/engine/base.py", line 1416, in execute
    return meth(
  File "/srv/talknet/backend/auth-service/venv/lib/python3.10/site-packages/sqlalchemy/sql/elements.py", line 517, in _execute_on_connection
    return connection._execute_clauseelement(
  File "/srv/talknet/backend/auth-service/venv/lib/python3.10/site-packages/sqlalchemy/engine/base.py", line 1639, in _execute_clauseelement
    ret = self._execute_context(
  File "/srv/talknet/backend/auth-service/venv/lib/python3.10/site-packages/sqlalchemy/engine/base.py", line 1848, in _execute_context
    return self._exec_single_context(
  File "/srv/talknet/backend/auth-service/venv/lib/python3.10/site-packages/sqlalchemy/engine/base.py", line 1988, in _exec_single_context
    self._handle_dbapi_exception(
  File "/srv/talknet/backend/auth-service/venv/lib/python3.10/site-packages/sqlalchemy/engine/base.py", line 2344, in _handle_dbapi_exception
    raise sqlalchemy_exception.with_traceback(exc_info[2]) from e
  File "/srv/talknet/backend/auth-service/venv/lib/python3.10/site-packages/sqlalchemy/engine/base.py", line 1969, in _exec_single_context
    self.dialect.do_execute(
  File "/srv/talknet/backend/auth-service/venv/lib/python3.10/site-packages/sqlalchemy/engine/default.py", line 922, in do_execute
    cursor.execute(statement, parameters)
sqlalchemy.exc.OperationalError: (sqlite3.OperationalError) no such table: user
[SQL: SELECT user.id AS user_id, user.username AS user_username, user.email AS user_email, user.password AS user_password 
FROM user 
WHERE user.email = ?
 LIMIT ? OFFSET ?]
[parameters: ('mykytashch@hotmail.com', 1, 0)]
(Background on this error at: https://sqlalche.me/e/20/e3q8)
[2024-02-10 01:43:39,484] ERROR in app: Exception on /register [POST]
Traceback (most recent call last):
  File "/srv/talknet/backend/auth-service/venv/lib/python3.10/site-packages/sqlalchemy/engine/base.py", line 1969, in _exec_single_context
    self.dialect.do_execute(
  File "/srv/talknet/backend/auth-service/venv/lib/python3.10/site-packages/sqlalchemy/engine/default.py", line 922, in do_execute
    cursor.execute(statement, parameters)
sqlite3.OperationalError: no such table: user

The above exception was the direct cause of the following exception:

Traceback (most recent call last):
  File "/srv/talknet/backend/auth-service/venv/lib/python3.10/site-packages/flask/app.py", line 1463, in wsgi_app
    response = self.full_dispatch_request()
  File "/srv/talknet/backend/auth-service/venv/lib/python3.10/site-packages/flask/app.py", line 872, in full_dispatch_request
    rv = self.handle_user_exception(e)
  File "/srv/talknet/backend/auth-service/venv/lib/python3.10/site-packages/flask_cors/extension.py", line 176, in wrapped_function
    return cors_after_request(app.make_response(f(*args, **kwargs)))
  File "/srv/talknet/backend/auth-service/venv/lib/python3.10/site-packages/flask/app.py", line 870, in full_dispatch_request
    rv = self.dispatch_request()
  File "/srv/talknet/backend/auth-service/venv/lib/python3.10/site-packages/flask/app.py", line 855, in dispatch_request
    return self.ensure_sync(self.view_functions[rule.endpoint])(**view_args)  # type: ignore[no-any-return]
  File "/srv/talknet/backend/auth-service/app.py", line 38, in register
    user = User.query.filter_by(email=data['email']).first()
  File "/srv/talknet/backend/auth-service/venv/lib/python3.10/site-packages/sqlalchemy/orm/query.py", line 2748, in first
    return self.limit(1)._iter().first()  # type: ignore
  File "/srv/talknet/backend/auth-service/venv/lib/python3.10/site-packages/sqlalchemy/orm/query.py", line 2847, in _iter
    result: Union[ScalarResult[_T], Result[_T]] = self.session.execute(
  File "/srv/talknet/backend/auth-service/venv/lib/python3.10/site-packages/sqlalchemy/orm/session.py", line 2308, in execute
    return self._execute_internal(
  File "/srv/talknet/backend/auth-service/venv/lib/python3.10/site-packages/sqlalchemy/orm/session.py", line 2190, in _execute_internal
    result: Result[Any] = compile_state_cls.orm_execute_statement(
  File "/srv/talknet/backend/auth-service/venv/lib/python3.10/site-packages/sqlalchemy/orm/context.py", line 293, in orm_execute_statement
    result = conn.execute(
  File "/srv/talknet/backend/auth-service/venv/lib/python3.10/site-packages/sqlalchemy/engine/base.py", line 1416, in execute
    return meth(
  File "/srv/talknet/backend/auth-service/venv/lib/python3.10/site-packages/sqlalchemy/sql/elements.py", line 517, in _execute_on_connection
    return connection._execute_clauseelement(
  File "/srv/talknet/backend/auth-service/venv/lib/python3.10/site-packages/sqlalchemy/engine/base.py", line 1639, in _execute_clauseelement
    ret = self._execute_context(
  File "/srv/talknet/backend/auth-service/venv/lib/python3.10/site-packages/sqlalchemy/engine/base.py", line 1848, in _execute_context
    return self._exec_single_context(
  File "/srv/talknet/backend/auth-service/venv/lib/python3.10/site-packages/sqlalchemy/engine/base.py", line 1988, in _exec_single_context
    self._handle_dbapi_exception(
  File "/srv/talknet/backend/auth-service/venv/lib/python3.10/site-packages/sqlalchemy/engine/base.py", line 2344, in _handle_dbapi_exception
    raise sqlalchemy_exception.with_traceback(exc_info[2]) from e
  File "/srv/talknet/backend/auth-service/venv/lib/python3.10/site-packages/sqlalchemy/engine/base.py", line 1969, in _exec_single_context
    self.dialect.do_execute(
  File "/srv/talknet/backend/auth-service/venv/lib/python3.10/site-packages/sqlalchemy/engine/default.py", line 922, in do_execute
    cursor.execute(statement, parameters)
sqlalchemy.exc.OperationalError: (sqlite3.OperationalError) no such table: user
[SQL: SELECT user.id AS user_id, user.username AS user_username, user.email AS user_email, user.password AS user_password 
FROM user 
WHERE user.email = ?
 LIMIT ? OFFSET ?]
[parameters: ('mykytashch@hotmail.com', 1, 0)]
(Background on this error at: https://sqlalche.me/e/20/e3q8)
[2024-02-10 01:43:39,486] ERROR in app: Exception on /login [POST]
Traceback (most recent call last):
  File "/srv/talknet/backend/auth-service/venv/lib/python3.10/site-packages/sqlalchemy/engine/base.py", line 1969, in _exec_single_context
    self.dialect.do_execute(
  File "/srv/talknet/backend/auth-service/venv/lib/python3.10/site-packages/sqlalchemy/engine/default.py", line 922, in do_execute
    cursor.execute(statement, parameters)
sqlite3.OperationalError: no such table: user

The above exception was the direct cause of the following exception:

Traceback (most recent call last):
  File "/srv/talknet/backend/auth-service/venv/lib/python3.10/site-packages/flask/app.py", line 1463, in wsgi_app
    response = self.full_dispatch_request()
  File "/srv/talknet/backend/auth-service/venv/lib/python3.10/site-packages/flask/app.py", line 872, in full_dispatch_request
    rv = self.handle_user_exception(e)
  File "/srv/talknet/backend/auth-service/venv/lib/python3.10/site-packages/flask_cors/extension.py", line 176, in wrapped_function
    return cors_after_request(app.make_response(f(*args, **kwargs)))
  File "/srv/talknet/backend/auth-service/venv/lib/python3.10/site-packages/flask/app.py", line 870, in full_dispatch_request
    rv = self.dispatch_request()
  File "/srv/talknet/backend/auth-service/venv/lib/python3.10/site-packages/flask/app.py", line 855, in dispatch_request
    return self.ensure_sync(self.view_functions[rule.endpoint])(**view_args)  # type: ignore[no-any-return]
  File "/srv/talknet/backend/auth-service/app.py", line 50, in login
    user = User.query.filter_by(email=data['email']).first()
  File "/srv/talknet/backend/auth-service/venv/lib/python3.10/site-packages/sqlalchemy/orm/query.py", line 2748, in first
    return self.limit(1)._iter().first()  # type: ignore
  File "/srv/talknet/backend/auth-service/venv/lib/python3.10/site-packages/sqlalchemy/orm/query.py", line 2847, in _iter
    result: Union[ScalarResult[_T], Result[_T]] = self.session.execute(
  File "/srv/talknet/backend/auth-service/venv/lib/python3.10/site-packages/sqlalchemy/orm/session.py", line 2308, in execute
    return self._execute_internal(
  File "/srv/talknet/backend/auth-service/venv/lib/python3.10/site-packages/sqlalchemy/orm/session.py", line 2190, in _execute_internal
    result: Result[Any] = compile_state_cls.orm_execute_statement(
  File "/srv/talknet/backend/auth-service/venv/lib/python3.10/site-packages/sqlalchemy/orm/context.py", line 293, in orm_execute_statement
    result = conn.execute(
  File "/srv/talknet/backend/auth-service/venv/lib/python3.10/site-packages/sqlalchemy/engine/base.py", line 1416, in execute
    return meth(
  File "/srv/talknet/backend/auth-service/venv/lib/python3.10/site-packages/sqlalchemy/sql/elements.py", line 517, in _execute_on_connection
    return connection._execute_clauseelement(
  File "/srv/talknet/backend/auth-service/venv/lib/python3.10/site-packages/sqlalchemy/engine/base.py", line 1639, in _execute_clauseelement
    ret = self._execute_context(
  File "/srv/talknet/backend/auth-service/venv/lib/python3.10/site-packages/sqlalchemy/engine/base.py", line 1848, in _execute_context
    return self._exec_single_context(
  File "/srv/talknet/backend/auth-service/venv/lib/python3.10/site-packages/sqlalchemy/engine/base.py", line 1988, in _exec_single_context
    self._handle_dbapi_exception(
  File "/srv/talknet/backend/auth-service/venv/lib/python3.10/site-packages/sqlalchemy/engine/base.py", line 2344, in _handle_dbapi_exception
    raise sqlalchemy_exception.with_traceback(exc_info[2]) from e
  File "/srv/talknet/backend/auth-service/venv/lib/python3.10/site-packages/sqlalchemy/engine/base.py", line 1969, in _exec_single_context
    self.dialect.do_execute(
  File "/srv/talknet/backend/auth-service/venv/lib/python3.10/site-packages/sqlalchemy/engine/default.py", line 922, in do_execute
    cursor.execute(statement, parameters)
sqlalchemy.exc.OperationalError: (sqlite3.OperationalError) no such table: user
[SQL: SELECT user.id AS user_id, user.username AS user_username, user.email AS user_email, user.password AS user_password 
FROM user 
WHERE user.email = ?
 LIMIT ? OFFSET ?]
[parameters: ('mykytashch@hotmail.com', 1, 0)]
(Background on this error at: https://sqlalche.me/e/20/e3q8)
[2024-02-10 01:43:39,488] ERROR in app: Exception on /login [POST]
Traceback (most recent call last):
  File "/srv/talknet/backend/auth-service/venv/lib/python3.10/site-packages/sqlalchemy/engine/base.py", line 1969, in _exec_single_context
    self.dialect.do_execute(
  File "/srv/talknet/backend/auth-service/venv/lib/python3.10/site-packages/sqlalchemy/engine/default.py", line 922, in do_execute
    cursor.execute(statement, parameters)
sqlite3.OperationalError: no such table: user

The above exception was the direct cause of the following exception:

Traceback (most recent call last):
  File "/srv/talknet/backend/auth-service/venv/lib/python3.10/site-packages/flask/app.py", line 1463, in wsgi_app
    response = self.full_dispatch_request()
  File "/srv/talknet/backend/auth-service/venv/lib/python3.10/site-packages/flask/app.py", line 872, in full_dispatch_request
    rv = self.handle_user_exception(e)
  File "/srv/talknet/backend/auth-service/venv/lib/python3.10/site-packages/flask_cors/extension.py", line 176, in wrapped_function
    return cors_after_request(app.make_response(f(*args, **kwargs)))
  File "/srv/talknet/backend/auth-service/venv/lib/python3.10/site-packages/flask/app.py", line 870, in full_dispatch_request
    rv = self.dispatch_request()
  File "/srv/talknet/backend/auth-service/venv/lib/python3.10/site-packages/flask/app.py", line 855, in dispatch_request
    return self.ensure_sync(self.view_functions[rule.endpoint])(**view_args)  # type: ignore[no-any-return]
  File "/srv/talknet/backend/auth-service/app.py", line 50, in login
    user = User.query.filter_by(email=data['email']).first()
  File "/srv/talknet/backend/auth-service/venv/lib/python3.10/site-packages/sqlalchemy/orm/query.py", line 2748, in first
    return self.limit(1)._iter().first()  # type: ignore
  File "/srv/talknet/backend/auth-service/venv/lib/python3.10/site-packages/sqlalchemy/orm/query.py", line 2847, in _iter
    result: Union[ScalarResult[_T], Result[_T]] = self.session.execute(
  File "/srv/talknet/backend/auth-service/venv/lib/python3.10/site-packages/sqlalchemy/orm/session.py", line 2308, in execute
    return self._execute_internal(
  File "/srv/talknet/backend/auth-service/venv/lib/python3.10/site-packages/sqlalchemy/orm/session.py", line 2190, in _execute_internal
    result: Result[Any] = compile_state_cls.orm_execute_statement(
  File "/srv/talknet/backend/auth-service/venv/lib/python3.10/site-packages/sqlalchemy/orm/context.py", line 293, in orm_execute_statement
    result = conn.execute(
  File "/srv/talknet/backend/auth-service/venv/lib/python3.10/site-packages/sqlalchemy/engine/base.py", line 1416, in execute
    return meth(
  File "/srv/talknet/backend/auth-service/venv/lib/python3.10/site-packages/sqlalchemy/sql/elements.py", line 517, in _execute_on_connection
    return connection._execute_clauseelement(
  File "/srv/talknet/backend/auth-service/venv/lib/python3.10/site-packages/sqlalchemy/engine/base.py", line 1639, in _execute_clauseelement
    ret = self._execute_context(
  File "/srv/talknet/backend/auth-service/venv/lib/python3.10/site-packages/sqlalchemy/engine/base.py", line 1848, in _execute_context
    return self._exec_single_context(
  File "/srv/talknet/backend/auth-service/venv/lib/python3.10/site-packages/sqlalchemy/engine/base.py", line 1988, in _exec_single_context
    self._handle_dbapi_exception(
  File "/srv/talknet/backend/auth-service/venv/lib/python3.10/site-packages/sqlalchemy/engine/base.py", line 2344, in _handle_dbapi_exception
    raise sqlalchemy_exception.with_traceback(exc_info[2]) from e
  File "/srv/talknet/backend/auth-service/venv/lib/python3.10/site-packages/sqlalchemy/engine/base.py", line 1969, in _exec_single_context
    self.dialect.do_execute(
  File "/srv/talknet/backend/auth-service/venv/lib/python3.10/site-packages/sqlalchemy/engine/default.py", line 922, in do_execute
    cursor.execute(statement, parameters)
sqlalchemy.exc.OperationalError: (sqlite3.OperationalError) no such table: user
[SQL: SELECT user.id AS user_id, user.username AS user_username, user.email AS user_email, user.password AS user_password 
FROM user 
WHERE user.email = ?
 LIMIT ? OFFSET ?]
[parameters: ('mykytashch@hotmail.com', 1, 0)]
(Background on this error at: https://sqlalche.me/e/20/e3q8)
[2024-02-10 01:43:39,504] ERROR in app: Exception on /login [POST]
Traceback (most recent call last):
  File "/srv/talknet/backend/auth-service/venv/lib/python3.10/site-packages/sqlalchemy/engine/base.py", line 1969, in _exec_single_context
    self.dialect.do_execute(
  File "/srv/talknet/backend/auth-service/venv/lib/python3.10/site-packages/sqlalchemy/engine/default.py", line 922, in do_execute
    cursor.execute(statement, parameters)
sqlite3.OperationalError: no such table: user

The above exception was the direct cause of the following exception:

Traceback (most recent call last):
  File "/srv/talknet/backend/auth-service/venv/lib/python3.10/site-packages/flask/app.py", line 1463, in wsgi_app
    response = self.full_dispatch_request()
  File "/srv/talknet/backend/auth-service/venv/lib/python3.10/site-packages/flask/app.py", line 872, in full_dispatch_request
    rv = self.handle_user_exception(e)
  File "/srv/talknet/backend/auth-service/venv/lib/python3.10/site-packages/flask_cors/extension.py", line 176, in wrapped_function
    return cors_after_request(app.make_response(f(*args, **kwargs)))
  File "/srv/talknet/backend/auth-service/venv/lib/python3.10/site-packages/flask/app.py", line 870, in full_dispatch_request
    rv = self.dispatch_request()
  File "/srv/talknet/backend/auth-service/venv/lib/python3.10/site-packages/flask/app.py", line 855, in dispatch_request
    return self.ensure_sync(self.view_functions[rule.endpoint])(**view_args)  # type: ignore[no-any-return]
  File "/srv/talknet/backend/auth-service/app.py", line 50, in login
    user = User.query.filter_by(email=data['email']).first()
  File "/srv/talknet/backend/auth-service/venv/lib/python3.10/site-packages/sqlalchemy/orm/query.py", line 2748, in first
    return self.limit(1)._iter().first()  # type: ignore
  File "/srv/talknet/backend/auth-service/venv/lib/python3.10/site-packages/sqlalchemy/orm/query.py", line 2847, in _iter
    result: Union[ScalarResult[_T], Result[_T]] = self.session.execute(
  File "/srv/talknet/backend/auth-service/venv/lib/python3.10/site-packages/sqlalchemy/orm/session.py", line 2308, in execute
    return self._execute_internal(
  File "/srv/talknet/backend/auth-service/venv/lib/python3.10/site-packages/sqlalchemy/orm/session.py", line 2190, in _execute_internal
    result: Result[Any] = compile_state_cls.orm_execute_statement(
  File "/srv/talknet/backend/auth-service/venv/lib/python3.10/site-packages/sqlalchemy/orm/context.py", line 293, in orm_execute_statement
    result = conn.execute(
  File "/srv/talknet/backend/auth-service/venv/lib/python3.10/site-packages/sqlalchemy/engine/base.py", line 1416, in execute
    return meth(
  File "/srv/talknet/backend/auth-service/venv/lib/python3.10/site-packages/sqlalchemy/sql/elements.py", line 517, in _execute_on_connection
    return connection._execute_clauseelement(
  File "/srv/talknet/backend/auth-service/venv/lib/python3.10/site-packages/sqlalchemy/engine/base.py", line 1639, in _execute_clauseelement
    ret = self._execute_context(
  File "/srv/talknet/backend/auth-service/venv/lib/python3.10/site-packages/sqlalchemy/engine/base.py", line 1848, in _execute_context
    return self._exec_single_context(
  File "/srv/talknet/backend/auth-service/venv/lib/python3.10/site-packages/sqlalchemy/engine/base.py", line 1988, in _exec_single_context
    self._handle_dbapi_exception(
  File "/srv/talknet/backend/auth-service/venv/lib/python3.10/site-packages/sqlalchemy/engine/base.py", line 2344, in _handle_dbapi_exception
    raise sqlalchemy_exception.with_traceback(exc_info[2]) from e
  File "/srv/talknet/backend/auth-service/venv/lib/python3.10/site-packages/sqlalchemy/engine/base.py", line 1969, in _exec_single_context
    self.dialect.do_execute(
  File "/srv/talknet/backend/auth-service/venv/lib/python3.10/site-packages/sqlalchemy/engine/default.py", line 922, in do_execute
    cursor.execute(statement, parameters)
sqlalchemy.exc.OperationalError: (sqlite3.OperationalError) no such table: user
[SQL: SELECT user.id AS user_id, user.username AS user_username, user.email AS user_email, user.password AS user_password 
FROM user 
WHERE user.email = ?
 LIMIT ? OFFSET ?]
[parameters: ('mykytashch@hotmail.com', 1, 0)]
(Background on this error at: https://sqlalche.me/e/20/e3q8)
[2024-02-10 01:43:39,506] ERROR in app: Exception on /login [POST]
Traceback (most recent call last):
  File "/srv/talknet/backend/auth-service/venv/lib/python3.10/site-packages/sqlalchemy/engine/base.py", line 1969, in _exec_single_context
    self.dialect.do_execute(
  File "/srv/talknet/backend/auth-service/venv/lib/python3.10/site-packages/sqlalchemy/engine/default.py", line 922, in do_execute
    cursor.execute(statement, parameters)
sqlite3.OperationalError: no such table: user

The above exception was the direct cause of the following exception:

Traceback (most recent call last):
  File "/srv/talknet/backend/auth-service/venv/lib/python3.10/site-packages/flask/app.py", line 1463, in wsgi_app
    response = self.full_dispatch_request()
  File "/srv/talknet/backend/auth-service/venv/lib/python3.10/site-packages/flask/app.py", line 872, in full_dispatch_request
    rv = self.handle_user_exception(e)
  File "/srv/talknet/backend/auth-service/venv/lib/python3.10/site-packages/flask_cors/extension.py", line 176, in wrapped_function
    return cors_after_request(app.make_response(f(*args, **kwargs)))
  File "/srv/talknet/backend/auth-service/venv/lib/python3.10/site-packages/flask/app.py", line 870, in full_dispatch_request
    rv = self.dispatch_request()
  File "/srv/talknet/backend/auth-service/venv/lib/python3.10/site-packages/flask/app.py", line 855, in dispatch_request
    return self.ensure_sync(self.view_functions[rule.endpoint])(**view_args)  # type: ignore[no-any-return]
  File "/srv/talknet/backend/auth-service/app.py", line 50, in login
    user = User.query.filter_by(email=data['email']).first()
  File "/srv/talknet/backend/auth-service/venv/lib/python3.10/site-packages/sqlalchemy/orm/query.py", line 2748, in first
    return self.limit(1)._iter().first()  # type: ignore
  File "/srv/talknet/backend/auth-service/venv/lib/python3.10/site-packages/sqlalchemy/orm/query.py", line 2847, in _iter
    result: Union[ScalarResult[_T], Result[_T]] = self.session.execute(
  File "/srv/talknet/backend/auth-service/venv/lib/python3.10/site-packages/sqlalchemy/orm/session.py", line 2308, in execute
    return self._execute_internal(
  File "/srv/talknet/backend/auth-service/venv/lib/python3.10/site-packages/sqlalchemy/orm/session.py", line 2190, in _execute_internal
    result: Result[Any] = compile_state_cls.orm_execute_statement(
  File "/srv/talknet/backend/auth-service/venv/lib/python3.10/site-packages/sqlalchemy/orm/context.py", line 293, in orm_execute_statement
    result = conn.execute(
  File "/srv/talknet/backend/auth-service/venv/lib/python3.10/site-packages/sqlalchemy/engine/base.py", line 1416, in execute
    return meth(
  File "/srv/talknet/backend/auth-service/venv/lib/python3.10/site-packages/sqlalchemy/sql/elements.py", line 517, in _execute_on_connection
    return connection._execute_clauseelement(
  File "/srv/talknet/backend/auth-service/venv/lib/python3.10/site-packages/sqlalchemy/engine/base.py", line 1639, in _execute_clauseelement
    ret = self._execute_context(
  File "/srv/talknet/backend/auth-service/venv/lib/python3.10/site-packages/sqlalchemy/engine/base.py", line 1848, in _execute_context
    return self._exec_single_context(
  File "/srv/talknet/backend/auth-service/venv/lib/python3.10/site-packages/sqlalchemy/engine/base.py", line 1988, in _exec_single_context
    self._handle_dbapi_exception(
  File "/srv/talknet/backend/auth-service/venv/lib/python3.10/site-packages/sqlalchemy/engine/base.py", line 2344, in _handle_dbapi_exception
    raise sqlalchemy_exception.with_traceback(exc_info[2]) from e
  File "/srv/talknet/backend/auth-service/venv/lib/python3.10/site-packages/sqlalchemy/engine/base.py", line 1969, in _exec_single_context
    self.dialect.do_execute(
  File "/srv/talknet/backend/auth-service/venv/lib/python3.10/site-packages/sqlalchemy/engine/default.py", line 922, in do_execute
    cursor.execute(statement, parameters)
sqlalchemy.exc.OperationalError: (sqlite3.OperationalError) no such table: user
[SQL: SELECT user.id AS user_id, user.username AS user_username, user.email AS user_email, user.password AS user_password 
FROM user 
WHERE user.email = ?
 LIMIT ? OFFSET ?]
[parameters: ('mykytashch@hotmail.com', 1, 0)]
(Background on this error at: https://sqlalche.me/e/20/e3q8)
[2024-02-10 01:43:39,516] ERROR in app: Exception on /login [POST]
Traceback (most recent call last):
  File "/srv/talknet/backend/auth-service/venv/lib/python3.10/site-packages/sqlalchemy/engine/base.py", line 1969, in _exec_single_context
    self.dialect.do_execute(
  File "/srv/talknet/backend/auth-service/venv/lib/python3.10/site-packages/sqlalchemy/engine/default.py", line 922, in do_execute
    cursor.execute(statement, parameters)
sqlite3.OperationalError: no such table: user

The above exception was the direct cause of the following exception:

Traceback (most recent call last):
  File "/srv/talknet/backend/auth-service/venv/lib/python3.10/site-packages/flask/app.py", line 1463, in wsgi_app
    response = self.full_dispatch_request()
  File "/srv/talknet/backend/auth-service/venv/lib/python3.10/site-packages/flask/app.py", line 872, in full_dispatch_request
    rv = self.handle_user_exception(e)
  File "/srv/talknet/backend/auth-service/venv/lib/python3.10/site-packages/flask_cors/extension.py", line 176, in wrapped_function
    return cors_after_request(app.make_response(f(*args, **kwargs)))
  File "/srv/talknet/backend/auth-service/venv/lib/python3.10/site-packages/flask/app.py", line 870, in full_dispatch_request
    rv = self.dispatch_request()
  File "/srv/talknet/backend/auth-service/venv/lib/python3.10/site-packages/flask/app.py", line 855, in dispatch_request
    return self.ensure_sync(self.view_functions[rule.endpoint])(**view_args)  # type: ignore[no-any-return]
  File "/srv/talknet/backend/auth-service/app.py", line 50, in login
    user = User.query.filter_by(email=data['email']).first()
  File "/srv/talknet/backend/auth-service/venv/lib/python3.10/site-packages/sqlalchemy/orm/query.py", line 2748, in first
    return self.limit(1)._iter().first()  # type: ignore
  File "/srv/talknet/backend/auth-service/venv/lib/python3.10/site-packages/sqlalchemy/orm/query.py", line 2847, in _iter
    result: Union[ScalarResult[_T], Result[_T]] = self.session.execute(
  File "/srv/talknet/backend/auth-service/venv/lib/python3.10/site-packages/sqlalchemy/orm/session.py", line 2308, in execute
    return self._execute_internal(
  File "/srv/talknet/backend/auth-service/venv/lib/python3.10/site-packages/sqlalchemy/orm/session.py", line 2190, in _execute_internal
    result: Result[Any] = compile_state_cls.orm_execute_statement(
  File "/srv/talknet/backend/auth-service/venv/lib/python3.10/site-packages/sqlalchemy/orm/context.py", line 293, in orm_execute_statement
    result = conn.execute(
  File "/srv/talknet/backend/auth-service/venv/lib/python3.10/site-packages/sqlalchemy/engine/base.py", line 1416, in execute
    return meth(
  File "/srv/talknet/backend/auth-service/venv/lib/python3.10/site-packages/sqlalchemy/sql/elements.py", line 517, in _execute_on_connection
    return connection._execute_clauseelement(
  File "/srv/talknet/backend/auth-service/venv/lib/python3.10/site-packages/sqlalchemy/engine/base.py", line 1639, in _execute_clauseelement
    ret = self._execute_context(
  File "/srv/talknet/backend/auth-service/venv/lib/python3.10/site-packages/sqlalchemy/engine/base.py", line 1848, in _execute_context
    return self._exec_single_context(
  File "/srv/talknet/backend/auth-service/venv/lib/python3.10/site-packages/sqlalchemy/engine/base.py", line 1988, in _exec_single_context
    self._handle_dbapi_exception(
  File "/srv/talknet/backend/auth-service/venv/lib/python3.10/site-packages/sqlalchemy/engine/base.py", line 2344, in _handle_dbapi_exception
    raise sqlalchemy_exception.with_traceback(exc_info[2]) from e
  File "/srv/talknet/backend/auth-service/venv/lib/python3.10/site-packages/sqlalchemy/engine/base.py", line 1969, in _exec_single_context
    self.dialect.do_execute(
  File "/srv/talknet/backend/auth-service/venv/lib/python3.10/site-packages/sqlalchemy/engine/default.py", line 922, in do_execute
    cursor.execute(statement, parameters)
sqlalchemy.exc.OperationalError: (sqlite3.OperationalError) no such table: user
[SQL: SELECT user.id AS user_id, user.username AS user_username, user.email AS user_email, user.password AS user_password 
FROM user 
WHERE user.email = ?
 LIMIT ? OFFSET ?]
[parameters: ('mykytashch@hotmail.com', 1, 0)]
(Background on this error at: https://sqlalche.me/e/20/e3q8)
[2024-02-10 01:43:39,518] ERROR in app: Exception on /login [POST]
Traceback (most recent call last):
  File "/srv/talknet/backend/auth-service/venv/lib/python3.10/site-packages/sqlalchemy/engine/base.py", line 1969, in _exec_single_context
    self.dialect.do_execute(
  File "/srv/talknet/backend/auth-service/venv/lib/python3.10/site-packages/sqlalchemy/engine/default.py", line 922, in do_execute
    cursor.execute(statement, parameters)
sqlite3.OperationalError: no such table: user

The above exception was the direct cause of the following exception:

Traceback (most recent call last):
  File "/srv/talknet/backend/auth-service/venv/lib/python3.10/site-packages/flask/app.py", line 1463, in wsgi_app
    response = self.full_dispatch_request()
  File "/srv/talknet/backend/auth-service/venv/lib/python3.10/site-packages/flask/app.py", line 872, in full_dispatch_request
    rv = self.handle_user_exception(e)
  File "/srv/talknet/backend/auth-service/venv/lib/python3.10/site-packages/flask_cors/extension.py", line 176, in wrapped_function
    return cors_after_request(app.make_response(f(*args, **kwargs)))
  File "/srv/talknet/backend/auth-service/venv/lib/python3.10/site-packages/flask/app.py", line 870, in full_dispatch_request
    rv = self.dispatch_request()
  File "/srv/talknet/backend/auth-service/venv/lib/python3.10/site-packages/flask/app.py", line 855, in dispatch_request
    return self.ensure_sync(self.view_functions[rule.endpoint])(**view_args)  # type: ignore[no-any-return]
  File "/srv/talknet/backend/auth-service/app.py", line 50, in login
    user = User.query.filter_by(email=data['email']).first()
  File "/srv/talknet/backend/auth-service/venv/lib/python3.10/site-packages/sqlalchemy/orm/query.py", line 2748, in first
    return self.limit(1)._iter().first()  # type: ignore
  File "/srv/talknet/backend/auth-service/venv/lib/python3.10/site-packages/sqlalchemy/orm/query.py", line 2847, in _iter
    result: Union[ScalarResult[_T], Result[_T]] = self.session.execute(
  File "/srv/talknet/backend/auth-service/venv/lib/python3.10/site-packages/sqlalchemy/orm/session.py", line 2308, in execute
    return self._execute_internal(
  File "/srv/talknet/backend/auth-service/venv/lib/python3.10/site-packages/sqlalchemy/orm/session.py", line 2190, in _execute_internal
    result: Result[Any] = compile_state_cls.orm_execute_statement(
  File "/srv/talknet/backend/auth-service/venv/lib/python3.10/site-packages/sqlalchemy/orm/context.py", line 293, in orm_execute_statement
    result = conn.execute(
  File "/srv/talknet/backend/auth-service/venv/lib/python3.10/site-packages/sqlalchemy/engine/base.py", line 1416, in execute
    return meth(
  File "/srv/talknet/backend/auth-service/venv/lib/python3.10/site-packages/sqlalchemy/sql/elements.py", line 517, in _execute_on_connection
    return connection._execute_clauseelement(
  File "/srv/talknet/backend/auth-service/venv/lib/python3.10/site-packages/sqlalchemy/engine/base.py", line 1639, in _execute_clauseelement
    ret = self._execute_context(
  File "/srv/talknet/backend/auth-service/venv/lib/python3.10/site-packages/sqlalchemy/engine/base.py", line 1848, in _execute_context
    return self._exec_single_context(
  File "/srv/talknet/backend/auth-service/venv/lib/python3.10/site-packages/sqlalchemy/engine/base.py", line 1988, in _exec_single_context
    self._handle_dbapi_exception(
  File "/srv/talknet/backend/auth-service/venv/lib/python3.10/site-packages/sqlalchemy/engine/base.py", line 2344, in _handle_dbapi_exception
    raise sqlalchemy_exception.with_traceback(exc_info[2]) from e
  File "/srv/talknet/backend/auth-service/venv/lib/python3.10/site-packages/sqlalchemy/engine/base.py", line 1969, in _exec_single_context
    self.dialect.do_execute(
  File "/srv/talknet/backend/auth-service/venv/lib/python3.10/site-packages/sqlalchemy/engine/default.py", line 922, in do_execute
    cursor.execute(statement, parameters)
sqlalchemy.exc.OperationalError: (sqlite3.OperationalError) no such table: user
[SQL: SELECT user.id AS user_id, user.username AS user_username, user.email AS user_email, user.password AS user_password 
FROM user 
WHERE user.email = ?
 LIMIT ? OFFSET ?]
[parameters: ('mykytashch@hotmail.com', 1, 0)]
(Background on this error at: https://sqlalche.me/e/20/e3q8)
[2024-02-10 01:44:19 +0000] [8166] [INFO] Starting gunicorn 21.2.0
[2024-02-10 01:44:19 +0000] [8166] [INFO] Listening at: http://0.0.0.0:8000 (8166)
[2024-02-10 01:44:19 +0000] [8166] [INFO] Using worker: sync
[2024-02-10 01:44:19 +0000] [8172] [INFO] Booting worker with pid: 8172
[2024-02-10 01:44:56 +0000] [8166] [CRITICAL] WORKER TIMEOUT (pid:8172)
[2024-02-10 01:44:56 +0000] [8172] [INFO] Worker exiting (pid: 8172)
[2024-02-10 01:44:56 +0000] [8166] [ERROR] Worker (pid:8172) exited with code 1
[2024-02-10 01:44:56 +0000] [8166] [ERROR] Worker (pid:8172) exited with code 1.
[2024-02-10 01:44:56 +0000] [8401] [INFO] Booting worker with pid: 8401
[2024-02-10 01:45:12,427] ERROR in app: Exception on /register [POST]
Traceback (most recent call last):
  File "/srv/talknet/backend/auth-service/venv/lib/python3.10/site-packages/sqlalchemy/engine/base.py", line 1969, in _exec_single_context
    self.dialect.do_execute(
  File "/srv/talknet/backend/auth-service/venv/lib/python3.10/site-packages/sqlalchemy/engine/default.py", line 922, in do_execute
    cursor.execute(statement, parameters)
sqlite3.OperationalError: no such table: user

The above exception was the direct cause of the following exception:

Traceback (most recent call last):
  File "/srv/talknet/backend/auth-service/venv/lib/python3.10/site-packages/flask/app.py", line 1463, in wsgi_app
    response = self.full_dispatch_request()
  File "/srv/talknet/backend/auth-service/venv/lib/python3.10/site-packages/flask/app.py", line 872, in full_dispatch_request
    rv = self.handle_user_exception(e)
  File "/srv/talknet/backend/auth-service/venv/lib/python3.10/site-packages/flask_cors/extension.py", line 176, in wrapped_function
    return cors_after_request(app.make_response(f(*args, **kwargs)))
  File "/srv/talknet/backend/auth-service/venv/lib/python3.10/site-packages/flask/app.py", line 870, in full_dispatch_request
    rv = self.dispatch_request()
  File "/srv/talknet/backend/auth-service/venv/lib/python3.10/site-packages/flask/app.py", line 855, in dispatch_request
    return self.ensure_sync(self.view_functions[rule.endpoint])(**view_args)  # type: ignore[no-any-return]
  File "/srv/talknet/backend/auth-service/app.py", line 38, in register
    user = User.query.filter_by(email=data['email']).first()
  File "/srv/talknet/backend/auth-service/venv/lib/python3.10/site-packages/sqlalchemy/orm/query.py", line 2748, in first
    return self.limit(1)._iter().first()  # type: ignore
  File "/srv/talknet/backend/auth-service/venv/lib/python3.10/site-packages/sqlalchemy/orm/query.py", line 2847, in _iter
    result: Union[ScalarResult[_T], Result[_T]] = self.session.execute(
  File "/srv/talknet/backend/auth-service/venv/lib/python3.10/site-packages/sqlalchemy/orm/session.py", line 2308, in execute
    return self._execute_internal(
  File "/srv/talknet/backend/auth-service/venv/lib/python3.10/site-packages/sqlalchemy/orm/session.py", line 2190, in _execute_internal
    result: Result[Any] = compile_state_cls.orm_execute_statement(
  File "/srv/talknet/backend/auth-service/venv/lib/python3.10/site-packages/sqlalchemy/orm/context.py", line 293, in orm_execute_statement
    result = conn.execute(
  File "/srv/talknet/backend/auth-service/venv/lib/python3.10/site-packages/sqlalchemy/engine/base.py", line 1416, in execute
    return meth(
  File "/srv/talknet/backend/auth-service/venv/lib/python3.10/site-packages/sqlalchemy/sql/elements.py", line 517, in _execute_on_connection
    return connection._execute_clauseelement(
  File "/srv/talknet/backend/auth-service/venv/lib/python3.10/site-packages/sqlalchemy/engine/base.py", line 1639, in _execute_clauseelement
    ret = self._execute_context(
  File "/srv/talknet/backend/auth-service/venv/lib/python3.10/site-packages/sqlalchemy/engine/base.py", line 1848, in _execute_context
    return self._exec_single_context(
  File "/srv/talknet/backend/auth-service/venv/lib/python3.10/site-packages/sqlalchemy/engine/base.py", line 1988, in _exec_single_context
    self._handle_dbapi_exception(
  File "/srv/talknet/backend/auth-service/venv/lib/python3.10/site-packages/sqlalchemy/engine/base.py", line 2344, in _handle_dbapi_exception
    raise sqlalchemy_exception.with_traceback(exc_info[2]) from e
  File "/srv/talknet/backend/auth-service/venv/lib/python3.10/site-packages/sqlalchemy/engine/base.py", line 1969, in _exec_single_context
    self.dialect.do_execute(
  File "/srv/talknet/backend/auth-service/venv/lib/python3.10/site-packages/sqlalchemy/engine/default.py", line 922, in do_execute
    cursor.execute(statement, parameters)
sqlalchemy.exc.OperationalError: (sqlite3.OperationalError) no such table: user
[SQL: SELECT user.id AS user_id, user.username AS user_username, user.email AS user_email, user.password AS user_password 
FROM user 
WHERE user.email = ?
 LIMIT ? OFFSET ?]
[parameters: ('mykytashch@hotmail.com', 1, 0)]
(Background on this error at: https://sqlalche.me/e/20/e3q8)
[2024-02-10 01:49:10 +0000] [9082] [INFO] Starting gunicorn 21.2.0
[2024-02-10 01:49:10 +0000] [9082] [ERROR] Connection in use: ('0.0.0.0', 8000)
[2024-02-10 01:49:10 +0000] [9082] [ERROR] Retrying in 1 second.
[2024-02-10 01:49:11 +0000] [9082] [ERROR] Connection in use: ('0.0.0.0', 8000)
[2024-02-10 01:49:11 +0000] [9082] [ERROR] Retrying in 1 second.
[2024-02-10 01:49:12 +0000] [9082] [INFO] Listening at: http://0.0.0.0:8000 (9082)
[2024-02-10 01:49:12 +0000] [9082] [INFO] Using worker: sync
[2024-02-10 01:49:12 +0000] [9128] [INFO] Booting worker with pid: 9128
[2024-02-10 01:50:03 +0000] [9082] [CRITICAL] WORKER TIMEOUT (pid:9128)
[2024-02-10 01:50:03 +0000] [9128] [INFO] Worker exiting (pid: 9128)
[2024-02-10 01:50:03 +0000] [9082] [ERROR] Worker (pid:9128) exited with code 1
[2024-02-10 01:50:03 +0000] [9082] [ERROR] Worker (pid:9128) exited with code 1.
[2024-02-10 01:50:03 +0000] [9305] [INFO] Booting worker with pid: 9305
[2024-02-10 01:54:16 +0000] [9930] [INFO] Starting gunicorn 21.2.0
[2024-02-10 01:54:16 +0000] [9930] [ERROR] Connection in use: ('0.0.0.0', 8000)
[2024-02-10 01:54:16 +0000] [9930] [ERROR] Retrying in 1 second.
[2024-02-10 01:54:17 +0000] [9930] [ERROR] Connection in use: ('0.0.0.0', 8000)
[2024-02-10 01:54:17 +0000] [9930] [ERROR] Retrying in 1 second.
[2024-02-10 01:54:18 +0000] [9930] [ERROR] Connection in use: ('0.0.0.0', 8000)
[2024-02-10 01:54:18 +0000] [9930] [ERROR] Retrying in 1 second.
[2024-02-10 01:54:19 +0000] [9930] [ERROR] Connection in use: ('0.0.0.0', 8000)
[2024-02-10 01:54:19 +0000] [9930] [ERROR] Retrying in 1 second.
[2024-02-10 01:54:20 +0000] [9930] [ERROR] Connection in use: ('0.0.0.0', 8000)
[2024-02-10 01:54:20 +0000] [9930] [ERROR] Retrying in 1 second.
[2024-02-10 01:54:21 +0000] [9930] [ERROR] Can't connect to ('0.0.0.0', 8000)
[2024-02-10 01:55:09 +0000] [10565] [INFO] Starting gunicorn 21.2.0
[2024-02-10 01:55:09 +0000] [10565] [INFO] Listening at: http://0.0.0.0:8000 (10565)
[2024-02-10 01:55:09 +0000] [10565] [INFO] Using worker: sync
[2024-02-10 01:55:09 +0000] [10566] [INFO] Booting worker with pid: 10566
[2024-02-10 01:56:07 +0000] [10565] [CRITICAL] WORKER TIMEOUT (pid:10566)
[2024-02-10 01:56:07 +0000] [10566] [INFO] Worker exiting (pid: 10566)
[2024-02-10 01:56:07 +0000] [10565] [ERROR] Worker (pid:10566) exited with code 1
[2024-02-10 01:56:07 +0000] [10565] [ERROR] Worker (pid:10566) exited with code 1.
[2024-02-10 01:56:07 +0000] [10738] [INFO] Booting worker with pid: 10738
