[2024-02-07 00:34:58 +0000] [2464139] [INFO] Starting gunicorn 21.2.0
[2024-02-07 00:34:58 +0000] [2464139] [INFO] Listening at: http://0.0.0.0:8000 (2464139)
[2024-02-07 00:34:58 +0000] [2464139] [INFO] Using worker: sync
[2024-02-07 00:34:58 +0000] [2464140] [INFO] Booting worker with pid: 2464140
[2024-02-07 00:34:58 +0000] [2464140] [ERROR] Exception in worker process
Traceback (most recent call last):
  File "/usr/local/lib/python3.10/dist-packages/gunicorn/arbiter.py", line 609, in spawn_worker
    worker.init_process()
  File "/usr/local/lib/python3.10/dist-packages/gunicorn/workers/base.py", line 134, in init_process
    self.load_wsgi()
  File "/usr/local/lib/python3.10/dist-packages/gunicorn/workers/base.py", line 146, in load_wsgi
    self.wsgi = self.app.wsgi()
  File "/usr/local/lib/python3.10/dist-packages/gunicorn/app/base.py", line 67, in wsgi
    self.callable = self.load()
  File "/usr/local/lib/python3.10/dist-packages/gunicorn/app/wsgiapp.py", line 58, in load
    return self.load_wsgiapp()
  File "/usr/local/lib/python3.10/dist-packages/gunicorn/app/wsgiapp.py", line 48, in load_wsgiapp
    return util.import_app(self.app_uri)
  File "/usr/local/lib/python3.10/dist-packages/gunicorn/util.py", line 371, in import_app
    mod = importlib.import_module(module)
  File "/usr/lib/python3.10/importlib/__init__.py", line 126, in import_module
    return _bootstrap._gcd_import(name[level:], package, level)
  File "<frozen importlib._bootstrap>", line 1050, in _gcd_import
  File "<frozen importlib._bootstrap>", line 1027, in _find_and_load
  File "<frozen importlib._bootstrap>", line 1006, in _find_and_load_unlocked
  File "<frozen importlib._bootstrap>", line 688, in _load_unlocked
  File "<frozen importlib._bootstrap_external>", line 883, in exec_module
  File "<frozen importlib._bootstrap>", line 241, in _call_with_frames_removed
  File "/srv/talknet/backend/auth-service/app.py", line 2, in <module>
    from flask import Flask, jsonify
ModuleNotFoundError: No module named 'flask'
[2024-02-07 00:34:58 +0000] [2464140] [INFO] Worker exiting (pid: 2464140)
[2024-02-07 00:34:58 +0000] [2464139] [ERROR] Worker (pid:2464140) exited with code 3
[2024-02-07 00:34:58 +0000] [2464139] [ERROR] Shutting down: Master
[2024-02-07 00:34:58 +0000] [2464139] [ERROR] Reason: Worker failed to boot.
[2024-02-07 00:36:48 +0000] [2476554] [INFO] Starting gunicorn 20.1.0
[2024-02-07 00:36:48 +0000] [2476554] [INFO] Listening at: http://0.0.0.0:8000 (2476554)
[2024-02-07 00:36:48 +0000] [2476554] [INFO] Using worker: sync
[2024-02-07 00:36:48 +0000] [2476555] [INFO] Booting worker with pid: 2476555
[2024-02-07 00:36:48 +0000] [2476555] [ERROR] Exception in worker process
Traceback (most recent call last):
  File "/usr/local/lib/python3.10/dist-packages/gunicorn/arbiter.py", line 589, in spawn_worker
    worker.init_process()
  File "/usr/local/lib/python3.10/dist-packages/gunicorn/workers/base.py", line 134, in init_process
    self.load_wsgi()
  File "/usr/local/lib/python3.10/dist-packages/gunicorn/workers/base.py", line 146, in load_wsgi
    self.wsgi = self.app.wsgi()
  File "/usr/local/lib/python3.10/dist-packages/gunicorn/app/base.py", line 67, in wsgi
    self.callable = self.load()
  File "/usr/local/lib/python3.10/dist-packages/gunicorn/app/wsgiapp.py", line 58, in load
    return self.load_wsgiapp()
  File "/usr/local/lib/python3.10/dist-packages/gunicorn/app/wsgiapp.py", line 48, in load_wsgiapp
    return util.import_app(self.app_uri)
  File "/usr/local/lib/python3.10/dist-packages/gunicorn/util.py", line 359, in import_app
    mod = importlib.import_module(module)
  File "/usr/lib/python3.10/importlib/__init__.py", line 126, in import_module
    return _bootstrap._gcd_import(name[level:], package, level)
  File "<frozen importlib._bootstrap>", line 1050, in _gcd_import
  File "<frozen importlib._bootstrap>", line 1027, in _find_and_load
  File "<frozen importlib._bootstrap>", line 1006, in _find_and_load_unlocked
  File "<frozen importlib._bootstrap>", line 688, in _load_unlocked
  File "<frozen importlib._bootstrap_external>", line 883, in exec_module
  File "<frozen importlib._bootstrap>", line 241, in _call_with_frames_removed
  File "/srv/talknet/backend/auth-service/app.py", line 2, in <module>
    from flask import Flask, jsonify
  File "/usr/local/lib/python3.10/dist-packages/flask/__init__.py", line 7, in <module>
    from .app import Flask as Flask
  File "/usr/local/lib/python3.10/dist-packages/flask/app.py", line 28, in <module>
    from . import cli
  File "/usr/local/lib/python3.10/dist-packages/flask/cli.py", line 18, in <module>
    from .helpers import get_debug_flag
  File "/usr/local/lib/python3.10/dist-packages/flask/helpers.py", line 16, in <module>
    from werkzeug.urls import url_quote
ImportError: cannot import name 'url_quote' from 'werkzeug.urls' (/usr/local/lib/python3.10/dist-packages/werkzeug/urls.py)
[2024-02-07 00:36:48 +0000] [2476555] [INFO] Worker exiting (pid: 2476555)
[2024-02-07 00:36:48 +0000] [2476554] [INFO] Shutting down: Master
[2024-02-07 00:36:48 +0000] [2476554] [INFO] Reason: Worker failed to boot.
